return {{["x"] = 4, ["meta"] = {["fields"] = {}, ["inventory"] = {}}, ["param2"] = 0, ["y"] = 0, ["param1"] = 15, ["z"] = 2, ["name"] = "default:goldblock"}, {["x"] = 4, ["meta"] = {["fields"] = {}, ["inventory"] = {}}, ["param2"] = 0, ["y"] = 0, ["param1"] = 15, ["z"] = 3, ["name"] = "default:goldblock"}, {["x"] = 4, ["meta"] = {["fields"] = {}, ["inventory"] = {}}, ["param2"] = 0, ["y"] = 0, ["param1"] = 15, ["z"] = 4, ["name"] = "default:goldblock"}, {["x"] = 4, ["meta"] = {["fields"] = {}, ["inventory"] = {}}, ["param2"] = 0, ["y"] = 0, ["param1"] = 15, ["z"] = 5, ["name"] = "default:goldblock"}, {["x"] = 4, ["meta"] = {["fields"] = {}, ["inventory"] = {}}, ["param2"] = 0, ["y"] = 0, ["param1"] = 15, ["z"] = 6, ["name"] = "default:goldblock"}, {["x"] = 4, ["meta"] = {["fields"] = {}, ["inventory"] = {}}, ["param2"] = 0, ["y"] = 1, ["param1"] = 15, ["z"] = 2, ["name"] = "default:goldblock"}, {["x"] = 4, ["meta"] = {["fields"] = {}, ["inventory"] = {}}, ["param2"] = 0, ["y"] = 1, ["param1"] = 15, ["z"] = 3, ["name"] = "default:goldblock"}, {["x"] = 4, ["meta"] = {["fields"] = {}, ["inventory"] = {}}, ["param2"] = 0, ["y"] = 1, ["param1"] = 15, ["z"] = 4, ["name"] = "default:goldblock"}, {["x"] = 4, ["meta"] = {["fields"] = {}, ["inventory"] = {}}, ["param2"] = 0, ["y"] = 1, ["param1"] = 15, ["z"] = 5, ["name"] = "default:goldblock"}, {["x"] = 4, ["meta"] = {["fields"] = {}, ["inventory"] = {}}, ["param2"] = 0, ["y"] = 1, ["param1"] = 15, ["z"] = 6, ["name"] = "default:goldblock"}, {["x"] = 4, ["meta"] = {["fields"] = {}, ["inventory"] = {}}, ["param2"] = 0, ["y"] = 2, ["param1"] = 15, ["z"] = 2, ["name"] = "default:goldblock"}, {["x"] = 4, ["meta"] = {["fields"] = {}, ["inventory"] = {}}, ["param2"] = 0, ["y"] = 2, ["param1"] = 15, ["z"] = 3, ["name"] = "default:goldblock"}, {["x"] = 4, ["meta"] = {["fields"] = {}, ["inventory"] = {}}, ["param2"] = 0, ["y"] = 2, ["param1"] = 15, ["z"] = 4, ["name"] = "default:goldblock"}, {["x"] = 4, ["meta"] = {["fields"] = {}, ["inventory"] = {}}, ["param2"] = 0, ["y"] = 2, ["param1"] = 15, ["z"] = 5, ["name"] = "default:goldblock"}, {["x"] = 4, ["meta"] = {["fields"] = {}, ["inventory"] = {}}, ["param2"] = 0, ["y"] = 2, ["param1"] = 15, ["z"] = 6, ["name"] = "default:goldblock"}, {["x"] = 4, ["meta"] = {["fields"] = {}, ["inventory"] = {}}, ["param2"] = 0, ["y"] = 3, ["param1"] = 15, ["z"] = 2, ["name"] = "default:goldblock"}, {["x"] = 4, ["meta"] = {["fields"] = {}, ["inventory"] = {}}, ["param2"] = 0, ["y"] = 3, ["param1"] = 15, ["z"] = 3, ["name"] = "default:goldblock"}, {["x"] = 4, ["meta"] = {["fields"] = {}, ["inventory"] = {}}, ["param2"] = 0, ["y"] = 3, ["param1"] = 15, ["z"] = 4, ["name"] = "default:goldblock"}, {["x"] = 4, ["meta"] = {["fields"] = {}, ["inventory"] = {}}, ["param2"] = 0, ["y"] = 3, ["param1"] = 15, ["z"] = 5, ["name"] = "default:goldblock"}, {["x"] = 4, ["meta"] = {["fields"] = {}, ["inventory"] = {}}, ["param2"] = 0, ["y"] = 3, ["param1"] = 15, ["z"] = 6, ["name"] = "default:goldblock"}, {["x"] = 4, ["meta"] = {["fields"] = {}, ["inventory"] = {}}, ["param2"] = 0, ["y"] = 4, ["param1"] = 15, ["z"] = 2, ["name"] = "default:goldblock"}, {["x"] = 4, ["meta"] = {["fields"] = {}, ["inventory"] = {}}, ["param2"] = 0, ["y"] = 4, ["param1"] = 15, ["z"] = 3, ["name"] = "default:goldblock"}, {["x"] = 4, ["meta"] = {["fields"] = {}, ["inventory"] = {}}, ["param2"] = 0, ["y"] = 4, ["param1"] = 15, ["z"] = 4, ["name"] = "default:goldblock"}, {["x"] = 4, ["meta"] = {["fields"] = {}, ["inventory"] = {}}, ["param2"] = 0, ["y"] = 4, ["param1"] = 15, ["z"] = 5, ["name"] = "default:goldblock"}, {["x"] = 4, ["meta"] = {["fields"] = {}, ["inventory"] = {}}, ["param2"] = 0, ["y"] = 4, ["param1"] = 15, ["z"] = 6, ["name"] = "default:goldblock"}, {["x"] = 4, ["meta"] = {["fields"] = {}, ["inventory"] = {}}, ["param2"] = 0, ["y"] = 5, ["param1"] = 15, ["z"] = 2, ["name"] = "default:goldblock"}, {["x"] = 4, ["meta"] = {["fields"] = {}, ["inventory"] = {}}, ["param2"] = 0, ["y"] = 5, ["param1"] = 15, ["z"] = 3, ["name"] = "default:goldblock"}, {["x"] = 4, ["meta"] = {["fields"] = {}, ["inventory"] = {}}, ["param2"] = 0, ["y"] = 5, ["param1"] = 15, ["z"] = 4, ["name"] = "default:goldblock"}, {["x"] = 4, ["meta"] = {["fields"] = {}, ["inventory"] = {}}, ["param2"] = 0, ["y"] = 5, ["param1"] = 15, ["z"] = 5, ["name"] = "default:goldblock"}, {["x"] = 4, ["meta"] = {["fields"] = {}, ["inventory"] = {}}, ["param2"] = 0, ["y"] = 5, ["param1"] = 15, ["z"] = 6, ["name"] = "default:goldblock"}, {["x"] = 4, ["meta"] = {["fields"] = {}, ["inventory"] = {}}, ["param2"] = 0, ["y"] = 6, ["param1"] = 15, ["z"] = 2, ["name"] = "default:goldblock"}, {["x"] = 4, ["meta"] = {["fields"] = {}, ["inventory"] = {}}, ["param2"] = 0, ["y"] = 6, ["param1"] = 15, ["z"] = 3, ["name"] = "default:goldblock"}, {["x"] = 4, ["meta"] = {["fields"] = {}, ["inventory"] = {}}, ["param2"] = 0, ["y"] = 6, ["param1"] = 15, ["z"] = 4, ["name"] = "default:goldblock"}, {["x"] = 4, ["meta"] = {["fields"] = {}, ["inventory"] = {}}, ["param2"] = 0, ["y"] = 6, ["param1"] = 15, ["z"] = 5, ["name"] = "default:goldblock"}, {["x"] = 4, ["meta"] = {["fields"] = {}, ["inventory"] = {}}, ["param2"] = 0, ["y"] = 6, ["param1"] = 15, ["z"] = 6, ["name"] = "default:goldblock"}, {["x"] = 5, ["meta"] = {["fields"] = {}, ["inventory"] = {}}, ["param2"] = 0, ["y"] = 0, ["param1"] = 15, ["z"] = 2, ["name"] = "default:goldblock"}, {["x"] = 5, ["meta"] = {["fields"] = {}, ["inventory"] = {}}, ["param2"] = 0, ["y"] = 0, ["param1"] = 15, ["z"] = 3, ["name"] = "default:goldblock"}, {["x"] = 5, ["meta"] = {["fields"] = {}, ["inventory"] = {}}, ["param2"] = 0, ["y"] = 0, ["param1"] = 15, ["z"] = 4, ["name"] = "default:goldblock"}, {["x"] = 5, ["meta"] = {["fields"] = {}, ["inventory"] = {}}, ["param2"] = 0, ["y"] = 0, ["param1"] = 15, ["z"] = 5, ["name"] = "default:goldblock"}, {["x"] = 5, ["meta"] = {["fields"] = {}, ["inventory"] = {}}, ["param2"] = 0, ["y"] = 0, ["param1"] = 15, ["z"] = 6, ["name"] = "default:goldblock"}, {["x"] = 5, ["meta"] = {["fields"] = {}, ["inventory"] = {}}, ["param2"] = 0, ["y"] = 1, ["param1"] = 15, ["z"] = 2, ["name"] = "default:goldblock"}, {["x"] = 5, ["meta"] = {["fields"] = {}, ["inventory"] = {}}, ["param2"] = 0, ["y"] = 1, ["param1"] = 15, ["z"] = 3, ["name"] = "default:goldblock"}, {["x"] = 5, ["meta"] = {["fields"] = {}, ["inventory"] = {}}, ["param2"] = 0, ["y"] = 1, ["param1"] = 15, ["z"] = 4, ["name"] = "default:goldblock"}, {["x"] = 5, ["meta"] = {["fields"] = {}, ["inventory"] = {}}, ["param2"] = 0, ["y"] = 1, ["param1"] = 15, ["z"] = 5, ["name"] = "default:goldblock"}, {["x"] = 5, ["meta"] = {["fields"] = {}, ["inventory"] = {}}, ["param2"] = 0, ["y"] = 1, ["param1"] = 15, ["z"] = 6, ["name"] = "default:goldblock"}, {["x"] = 5, ["meta"] = {["fields"] = {}, ["inventory"] = {}}, ["param2"] = 0, ["y"] = 2, ["param1"] = 15, ["z"] = 2, ["name"] = "default:goldblock"}, {["x"] = 5, ["meta"] = {["fields"] = {}, ["inventory"] = {}}, ["param2"] = 0, ["y"] = 2, ["param1"] = 15, ["z"] = 3, ["name"] = "default:goldblock"}, {["x"] = 5, ["meta"] = {["fields"] = {}, ["inventory"] = {}}, ["param2"] = 0, ["y"] = 2, ["param1"] = 15, ["z"] = 4, ["name"] = "default:goldblock"}, {["x"] = 5, ["meta"] = {["fields"] = {}, ["inventory"] = {}}, ["param2"] = 0, ["y"] = 2, ["param1"] = 15, ["z"] = 5, ["name"] = "default:goldblock"}, {["x"] = 5, ["meta"] = {["fields"] = {}, ["inventory"] = {}}, ["param2"] = 0, ["y"] = 2, ["param1"] = 15, ["z"] = 6, ["name"] = "default:goldblock"}, {["x"] = 5, ["meta"] = {["fields"] = {}, ["inventory"] = {}}, ["param2"] = 0, ["y"] = 3, ["param1"] = 15, ["z"] = 2, ["name"] = "default:goldblock"}, {["x"] = 5, ["meta"] = {["fields"] = {}, ["inventory"] = {}}, ["param2"] = 0, ["y"] = 3, ["param1"] = 15, ["z"] = 3, ["name"] = "default:goldblock"}, {["x"] = 5, ["meta"] = {["fields"] = {}, ["inventory"] = {}}, ["param2"] = 0, ["y"] = 3, ["param1"] = 15, ["z"] = 4, ["name"] = "default:goldblock"}, {["x"] = 5, ["meta"] = {["fields"] = {}, ["inventory"] = {}}, ["param2"] = 0, ["y"] = 3, ["param1"] = 15, ["z"] = 5, ["name"] = "default:goldblock"}, {["x"] = 5, ["meta"] = {["fields"] = {}, ["inventory"] = {}}, ["param2"] = 0, ["y"] = 3, ["param1"] = 15, ["z"] = 6, ["name"] = "default:goldblock"}, {["x"] = 5, ["meta"] = {["fields"] = {}, ["inventory"] = {}}, ["param2"] = 0, ["y"] = 4, ["param1"] = 15, ["z"] = 2, ["name"] = "default:goldblock"}, {["x"] = 5, ["meta"] = {["fields"] = {}, ["inventory"] = {}}, ["param2"] = 0, ["y"] = 4, ["param1"] = 15, ["z"] = 3, ["name"] = "default:goldblock"}, {["x"] = 5, ["meta"] = {["fields"] = {}, ["inventory"] = {}}, ["param2"] = 0, ["y"] = 4, ["param1"] = 15, ["z"] = 4, ["name"] = "default:goldblock"}, {["x"] = 5, ["meta"] = {["fields"] = {}, ["inventory"] = {}}, ["param2"] = 0, ["y"] = 4, ["param1"] = 15, ["z"] = 5, ["name"] = "default:goldblock"}, {["x"] = 5, ["meta"] = {["fields"] = {}, ["inventory"] = {}}, ["param2"] = 0, ["y"] = 4, ["param1"] = 15, ["z"] = 6, ["name"] = "default:goldblock"}, {["x"] = 5, ["meta"] = {["fields"] = {}, ["inventory"] = {}}, ["param2"] = 0, ["y"] = 5, ["param1"] = 15, ["z"] = 2, ["name"] = "default:goldblock"}, {["x"] = 5, ["meta"] = {["fields"] = {}, ["inventory"] = {}}, ["param2"] = 0, ["y"] = 5, ["param1"] = 15, ["z"] = 3, ["name"] = "default:goldblock"}, {["x"] = 5, ["meta"] = {["fields"] = {}, ["inventory"] = {}}, ["param2"] = 0, ["y"] = 5, ["param1"] = 15, ["z"] = 4, ["name"] = "default:goldblock"}, {["x"] = 5, ["meta"] = {["fields"] = {}, ["inventory"] = {}}, ["param2"] = 0, ["y"] = 5, ["param1"] = 15, ["z"] = 5, ["name"] = "default:goldblock"}, {["x"] = 5, ["meta"] = {["fields"] = {}, ["inventory"] = {}}, ["param2"] = 0, ["y"] = 5, ["param1"] = 15, ["z"] = 6, ["name"] = "default:goldblock"}, {["x"] = 5, ["meta"] = {["fields"] = {}, ["inventory"] = {}}, ["param2"] = 0, ["y"] = 6, ["param1"] = 15, ["z"] = 2, ["name"] = "default:goldblock"}, {["x"] = 5, ["meta"] = {["fields"] = {}, ["inventory"] = {}}, ["param2"] = 0, ["y"] = 6, ["param1"] = 15, ["z"] = 3, ["name"] = "default:goldblock"}, {["x"] = 5, ["meta"] = {["fields"] = {}, ["inventory"] = {}}, ["param2"] = 0, ["y"] = 6, ["param1"] = 15, ["z"] = 4, ["name"] = "default:goldblock"}, {["x"] = 5, ["meta"] = {["fields"] = {}, ["inventory"] = {}}, ["param2"] = 0, ["y"] = 6, ["param1"] = 15, ["z"] = 5, ["name"] = "default:goldblock"}, {["x"] = 5, ["meta"] = {["fields"] = {}, ["inventory"] = {}}, ["param2"] = 0, ["y"] = 6, ["param1"] = 15, ["z"] = 6, ["name"] = "default:goldblock"}, {["x"] = 6, ["meta"] = {["fields"] = {}, ["inventory"] = {}}, ["param2"] = 0, ["y"] = 0, ["param1"] = 15, ["z"] = 2, ["name"] = "default:goldblock"}, {["x"] = 6, ["meta"] = {["fields"] = {}, ["inventory"] = {}}, ["param2"] = 0, ["y"] = 0, ["param1"] = 15, ["z"] = 3, ["name"] = "default:goldblock"}, {["x"] = 6, ["meta"] = {["fields"] = {}, ["inventory"] = {}}, ["param2"] = 0, ["y"] = 0, ["param1"] = 15, ["z"] = 4, ["name"] = "default:goldblock"}, {["x"] = 6, ["meta"] = {["fields"] = {}, ["inventory"] = {}}, ["param2"] = 0, ["y"] = 0, ["param1"] = 15, ["z"] = 5, ["name"] = "default:goldblock"}, {["x"] = 6, ["meta"] = {["fields"] = {}, ["inventory"] = {}}, ["param2"] = 0, ["y"] = 0, ["param1"] = 15, ["z"] = 6, ["name"] = "default:goldblock"}, {["x"] = 6, ["meta"] = {["fields"] = {}, ["inventory"] = {}}, ["param2"] = 0, ["y"] = 1, ["param1"] = 15, ["z"] = 2, ["name"] = "default:goldblock"}, {["x"] = 6, ["meta"] = {["fields"] = {}, ["inventory"] = {}}, ["param2"] = 0, ["y"] = 1, ["param1"] = 15, ["z"] = 3, ["name"] = "default:goldblock"}, {["x"] = 6, ["meta"] = {["fields"] = {}, ["inventory"] = {}}, ["param2"] = 0, ["y"] = 1, ["param1"] = 15, ["z"] = 4, ["name"] = "default:goldblock"}, {["x"] = 6, ["meta"] = {["fields"] = {}, ["inventory"] = {}}, ["param2"] = 0, ["y"] = 1, ["param1"] = 15, ["z"] = 5, ["name"] = "default:goldblock"}, {["x"] = 6, ["meta"] = {["fields"] = {}, ["inventory"] = {}}, ["param2"] = 0, ["y"] = 1, ["param1"] = 15, ["z"] = 6, ["name"] = "default:goldblock"}, {["x"] = 6, ["meta"] = {["fields"] = {}, ["inventory"] = {}}, ["param2"] = 0, ["y"] = 2, ["param1"] = 15, ["z"] = 2, ["name"] = "default:goldblock"}, {["x"] = 6, ["meta"] = {["fields"] = {}, ["inventory"] = {}}, ["param2"] = 0, ["y"] = 2, ["param1"] = 15, ["z"] = 3, ["name"] = "default:goldblock"}, {["x"] = 6, ["meta"] = {["fields"] = {}, ["inventory"] = {}}, ["param2"] = 0, ["y"] = 2, ["param1"] = 15, ["z"] = 4, ["name"] = "default:goldblock"}, {["x"] = 6, ["meta"] = {["fields"] = {}, ["inventory"] = {}}, ["param2"] = 0, ["y"] = 2, ["param1"] = 15, ["z"] = 5, ["name"] = "default:goldblock"}, {["x"] = 6, ["meta"] = {["fields"] = {}, ["inventory"] = {}}, ["param2"] = 0, ["y"] = 2, ["param1"] = 15, ["z"] = 6, ["name"] = "default:goldblock"}, {["x"] = 6, ["meta"] = {["fields"] = {}, ["inventory"] = {}}, ["param2"] = 0, ["y"] = 3, ["param1"] = 15, ["z"] = 2, ["name"] = "default:goldblock"}, {["x"] = 6, ["meta"] = {["fields"] = {}, ["inventory"] = {}}, ["param2"] = 0, ["y"] = 3, ["param1"] = 15, ["z"] = 3, ["name"] = "default:goldblock"}, {["x"] = 6, ["meta"] = {["fields"] = {}, ["inventory"] = {}}, ["param2"] = 0, ["y"] = 3, ["param1"] = 15, ["z"] = 4, ["name"] = "default:goldblock"}, {["x"] = 6, ["meta"] = {["fields"] = {}, ["inventory"] = {}}, ["param2"] = 0, ["y"] = 3, ["param1"] = 15, ["z"] = 5, ["name"] = "default:goldblock"}, {["x"] = 6, ["meta"] = {["fields"] = {}, ["inventory"] = {}}, ["param2"] = 0, ["y"] = 3, ["param1"] = 15, ["z"] = 6, ["name"] = "default:goldblock"}, {["x"] = 6, ["meta"] = {["fields"] = {}, ["inventory"] = {}}, ["param2"] = 0, ["y"] = 4, ["param1"] = 15, ["z"] = 2, ["name"] = "default:goldblock"}, {["x"] = 6, ["meta"] = {["fields"] = {}, ["inventory"] = {}}, ["param2"] = 0, ["y"] = 4, ["param1"] = 15, ["z"] = 3, ["name"] = "default:goldblock"}, {["x"] = 6, ["meta"] = {["fields"] = {}, ["inventory"] = {}}, ["param2"] = 0, ["y"] = 4, ["param1"] = 15, ["z"] = 4, ["name"] = "default:goldblock"}, {["x"] = 6, ["meta"] = {["fields"] = {}, ["inventory"] = {}}, ["param2"] = 0, ["y"] = 4, ["param1"] = 15, ["z"] = 5, ["name"] = "default:goldblock"}, {["x"] = 6, ["meta"] = {["fields"] = {}, ["inventory"] = {}}, ["param2"] = 0, ["y"] = 4, ["param1"] = 15, ["z"] = 6, ["name"] = "default:goldblock"}, {["x"] = 6, ["meta"] = {["fields"] = {}, ["inventory"] = {}}, ["param2"] = 0, ["y"] = 5, ["param1"] = 15, ["z"] = 2, ["name"] = "default:goldblock"}, {["x"] = 6, ["meta"] = {["fields"] = {}, ["inventory"] = {}}, ["param2"] = 0, ["y"] = 5, ["param1"] = 15, ["z"] = 3, ["name"] = "default:goldblock"}, {["x"] = 6, ["meta"] = {["fields"] = {}, ["inventory"] = {}}, ["param2"] = 0, ["y"] = 5, ["param1"] = 15, ["z"] = 4, ["name"] = "default:goldblock"}, {["x"] = 6, ["meta"] = {["fields"] = {}, ["inventory"] = {}}, ["param2"] = 0, ["y"] = 5, ["param1"] = 15, ["z"] = 5, ["name"] = "default:goldblock"}, {["x"] = 6, ["meta"] = {["fields"] = {}, ["inventory"] = {}}, ["param2"] = 0, ["y"] = 5, ["param1"] = 15, ["z"] = 6, ["name"] = "default:goldblock"}, {["x"] = 6, ["meta"] = {["fields"] = {}, ["inventory"] = {}}, ["param2"] = 0, ["y"] = 6, ["param1"] = 15, ["z"] = 2, ["name"] = "default:goldblock"}, {["x"] = 6, ["meta"] = {["fields"] = {}, ["inventory"] = {}}, ["param2"] = 0, ["y"] = 6, ["param1"] = 15, ["z"] = 3, ["name"] = "default:goldblock"}, {["x"] = 6, ["meta"] = {["fields"] = {}, ["inventory"] = {}}, ["param2"] = 0, ["y"] = 6, ["param1"] = 15, ["z"] = 4, ["name"] = "default:goldblock"}, {["x"] = 6, ["meta"] = {["fields"] = {}, ["inventory"] = {}}, ["param2"] = 0, ["y"] = 6, ["param1"] = 15, ["z"] = 5, ["name"] = "default:goldblock"}, {["x"] = 6, ["meta"] = {["fields"] = {}, ["inventory"] = {}}, ["param2"] = 0, ["y"] = 6, ["param1"] = 15, ["z"] = 6, ["name"] = "default:goldblock"}, {["x"] = 7, ["meta"] = {["fields"] = {}, ["inventory"] = {}}, ["param2"] = 0, ["y"] = 0, ["param1"] = 15, ["z"] = 2, ["name"] = "default:goldblock"}, {["x"] = 7, ["meta"] = {["fields"] = {}, ["inventory"] = {}}, ["param2"] = 0, ["y"] = 0, ["param1"] = 15, ["z"] = 3, ["name"] = "default:goldblock"}, {["x"] = 7, ["meta"] = {["fields"] = {}, ["inventory"] = {}}, ["param2"] = 0, ["y"] = 0, ["param1"] = 15, ["z"] = 4, ["name"] = "default:goldblock"}, {["x"] = 7, ["meta"] = {["fields"] = {}, ["inventory"] = {}}, ["param2"] = 0, ["y"] = 0, ["param1"] = 15, ["z"] = 5, ["name"] = "default:goldblock"}, {["x"] = 7, ["meta"] = {["fields"] = {}, ["inventory"] = {}}, ["param2"] = 0, ["y"] = 0, ["param1"] = 15, ["z"] = 6, ["name"] = "default:goldblock"}, {["x"] = 7, ["meta"] = {["fields"] = {}, ["inventory"] = {}}, ["param2"] = 0, ["y"] = 1, ["param1"] = 15, ["z"] = 2, ["name"] = "default:goldblock"}, {["x"] = 7, ["meta"] = {["fields"] = {}, ["inventory"] = {}}, ["param2"] = 0, ["y"] = 1, ["param1"] = 15, ["z"] = 3, ["name"] = "default:goldblock"}, {["x"] = 7, ["meta"] = {["fields"] = {}, ["inventory"] = {}}, ["param2"] = 0, ["y"] = 1, ["param1"] = 15, ["z"] = 4, ["name"] = "default:goldblock"}, {["x"] = 7, ["meta"] = {["fields"] = {}, ["inventory"] = {}}, ["param2"] = 0, ["y"] = 1, ["param1"] = 15, ["z"] = 5, ["name"] = "default:goldblock"}, {["x"] = 7, ["meta"] = {["fields"] = {}, ["inventory"] = {}}, ["param2"] = 0, ["y"] = 1, ["param1"] = 15, ["z"] = 6, ["name"] = "default:goldblock"}, {["x"] = 7, ["meta"] = {["fields"] = {}, ["inventory"] = {}}, ["param2"] = 0, ["y"] = 2, ["param1"] = 15, ["z"] = 2, ["name"] = "default:goldblock"}, {["x"] = 7, ["meta"] = {["fields"] = {}, ["inventory"] = {}}, ["param2"] = 0, ["y"] = 2, ["param1"] = 15, ["z"] = 3, ["name"] = "default:goldblock"}, {["x"] = 7, ["meta"] = {["fields"] = {}, ["inventory"] = {}}, ["param2"] = 0, ["y"] = 2, ["param1"] = 15, ["z"] = 4, ["name"] = "default:goldblock"}, {["x"] = 7, ["meta"] = {["fields"] = {}, ["inventory"] = {}}, ["param2"] = 0, ["y"] = 2, ["param1"] = 15, ["z"] = 5, ["name"] = "default:goldblock"}, {["x"] = 7, ["meta"] = {["fields"] = {}, ["inventory"] = {}}, ["param2"] = 0, ["y"] = 2, ["param1"] = 15, ["z"] = 6, ["name"] = "default:goldblock"}, {["x"] = 7, ["meta"] = {["fields"] = {}, ["inventory"] = {}}, ["param2"] = 0, ["y"] = 3, ["param1"] = 15, ["z"] = 2, ["name"] = "default:goldblock"}, {["x"] = 7, ["meta"] = {["fields"] = {}, ["inventory"] = {}}, ["param2"] = 0, ["y"] = 3, ["param1"] = 15, ["z"] = 3, ["name"] = "default:goldblock"}, {["x"] = 7, ["meta"] = {["fields"] = {}, ["inventory"] = {}}, ["param2"] = 0, ["y"] = 3, ["param1"] = 15, ["z"] = 4, ["name"] = "default:goldblock"}, {["x"] = 7, ["meta"] = {["fields"] = {}, ["inventory"] = {}}, ["param2"] = 0, ["y"] = 3, ["param1"] = 15, ["z"] = 5, ["name"] = "default:goldblock"}, {["x"] = 7, ["meta"] = {["fields"] = {}, ["inventory"] = {}}, ["param2"] = 0, ["y"] = 3, ["param1"] = 15, ["z"] = 6, ["name"] = "default:goldblock"}, {["x"] = 7, ["meta"] = {["fields"] = {}, ["inventory"] = {}}, ["param2"] = 0, ["y"] = 4, ["param1"] = 15, ["z"] = 2, ["name"] = "default:goldblock"}, {["x"] = 7, ["meta"] = {["fields"] = {}, ["inventory"] = {}}, ["param2"] = 0, ["y"] = 4, ["param1"] = 15, ["z"] = 3, ["name"] = "default:goldblock"}, {["x"] = 7, ["meta"] = {["fields"] = {}, ["inventory"] = {}}, ["param2"] = 0, ["y"] = 4, ["param1"] = 15, ["z"] = 4, ["name"] = "default:goldblock"}, {["x"] = 7, ["meta"] = {["fields"] = {}, ["inventory"] = {}}, ["param2"] = 0, ["y"] = 4, ["param1"] = 15, ["z"] = 5, ["name"] = "default:goldblock"}, {["x"] = 7, ["meta"] = {["fields"] = {}, ["inventory"] = {}}, ["param2"] = 0, ["y"] = 4, ["param1"] = 15, ["z"] = 6, ["name"] = "default:goldblock"}, {["x"] = 7, ["meta"] = {["fields"] = {}, ["inventory"] = {}}, ["param2"] = 0, ["y"] = 5, ["param1"] = 15, ["z"] = 2, ["name"] = "default:goldblock"}, {["x"] = 7, ["meta"] = {["fields"] = {}, ["inventory"] = {}}, ["param2"] = 0, ["y"] = 5, ["param1"] = 15, ["z"] = 3, ["name"] = "default:goldblock"}, {["x"] = 7, ["meta"] = {["fields"] = {}, ["inventory"] = {}}, ["param2"] = 0, ["y"] = 5, ["param1"] = 15, ["z"] = 4, ["name"] = "default:goldblock"}, {["x"] = 7, ["meta"] = {["fields"] = {}, ["inventory"] = {}}, ["param2"] = 0, ["y"] = 5, ["param1"] = 15, ["z"] = 5, ["name"] = "default:goldblock"}, {["x"] = 7, ["meta"] = {["fields"] = {}, ["inventory"] = {}}, ["param2"] = 0, ["y"] = 5, ["param1"] = 15, ["z"] = 6, ["name"] = "default:goldblock"}, {["x"] = 7, ["meta"] = {["fields"] = {}, ["inventory"] = {}}, ["param2"] = 0, ["y"] = 6, ["param1"] = 15, ["z"] = 2, ["name"] = "default:goldblock"}, {["x"] = 7, ["meta"] = {["fields"] = {}, ["inventory"] = {}}, ["param2"] = 0, ["y"] = 6, ["param1"] = 15, ["z"] = 3, ["name"] = "default:goldblock"}, {["x"] = 7, ["meta"] = {["fields"] = {}, ["inventory"] = {}}, ["param2"] = 0, ["y"] = 6, ["param1"] = 15, ["z"] = 4, ["name"] = "default:goldblock"}, {["x"] = 7, ["meta"] = {["fields"] = {}, ["inventory"] = {}}, ["param2"] = 0, ["y"] = 6, ["param1"] = 15, ["z"] = 5, ["name"] = "default:goldblock"}, {["x"] = 7, ["meta"] = {["fields"] = {}, ["inventory"] = {}}, ["param2"] = 0, ["y"] = 6, ["param1"] = 15, ["z"] = 6, ["name"] = "default:goldblock"}, {["x"] = 8, ["meta"] = {["fields"] = {}, ["inventory"] = {}}, ["param2"] = 0, ["y"] = 0, ["param1"] = 15, ["z"] = 2, ["name"] = "default:goldblock"}, {["x"] = 8, ["meta"] = {["fields"] = {}, ["inventory"] = {}}, ["param2"] = 0, ["y"] = 0, ["param1"] = 15, ["z"] = 3, ["name"] = "default:goldblock"}, {["x"] = 8, ["meta"] = {["fields"] = {}, ["inventory"] = {}}, ["param2"] = 0, ["y"] = 0, ["param1"] = 15, ["z"] = 4, ["name"] = "default:goldblock"}, {["x"] = 8, ["meta"] = {["fields"] = {}, ["inventory"] = {}}, ["param2"] = 0, ["y"] = 0, ["param1"] = 15, ["z"] = 5, ["name"] = "default:goldblock"}, {["x"] = 8, ["meta"] = {["fields"] = {}, ["inventory"] = {}}, ["param2"] = 0, ["y"] = 0, ["param1"] = 15, ["z"] = 6, ["name"] = "default:goldblock"}, {["x"] = 8, ["meta"] = {["fields"] = {}, ["inventory"] = {}}, ["param2"] = 0, ["y"] = 1, ["param1"] = 15, ["z"] = 2, ["name"] = "default:goldblock"}, {["x"] = 8, ["meta"] = {["fields"] = {}, ["inventory"] = {}}, ["param2"] = 0, ["y"] = 1, ["param1"] = 15, ["z"] = 3, ["name"] = "default:goldblock"}, {["x"] = 8, ["meta"] = {["fields"] = {}, ["inventory"] = {}}, ["param2"] = 0, ["y"] = 1, ["param1"] = 15, ["z"] = 4, ["name"] = "default:goldblock"}, {["x"] = 8, ["meta"] = {["fields"] = {}, ["inventory"] = {}}, ["param2"] = 0, ["y"] = 1, ["param1"] = 15, ["z"] = 5, ["name"] = "default:goldblock"}, {["x"] = 8, ["meta"] = {["fields"] = {}, ["inventory"] = {}}, ["param2"] = 0, ["y"] = 1, ["param1"] = 15, ["z"] = 6, ["name"] = "default:goldblock"}, {["x"] = 8, ["meta"] = {["fields"] = {}, ["inventory"] = {}}, ["param2"] = 0, ["y"] = 2, ["param1"] = 15, ["z"] = 2, ["name"] = "default:goldblock"}, {["x"] = 8, ["meta"] = {["fields"] = {}, ["inventory"] = {}}, ["param2"] = 0, ["y"] = 2, ["param1"] = 15, ["z"] = 3, ["name"] = "default:goldblock"}, {["x"] = 8, ["meta"] = {["fields"] = {}, ["inventory"] = {}}, ["param2"] = 0, ["y"] = 2, ["param1"] = 15, ["z"] = 4, ["name"] = "default:goldblock"}, {["x"] = 8, ["meta"] = {["fields"] = {}, ["inventory"] = {}}, ["param2"] = 0, ["y"] = 2, ["param1"] = 15, ["z"] = 5, ["name"] = "default:goldblock"}, {["x"] = 8, ["meta"] = {["fields"] = {}, ["inventory"] = {}}, ["param2"] = 0, ["y"] = 2, ["param1"] = 15, ["z"] = 6, ["name"] = "default:goldblock"}, {["x"] = 8, ["meta"] = {["fields"] = {}, ["inventory"] = {}}, ["param2"] = 0, ["y"] = 3, ["param1"] = 15, ["z"] = 2, ["name"] = "default:goldblock"}, {["x"] = 8, ["meta"] = {["fields"] = {}, ["inventory"] = {}}, ["param2"] = 0, ["y"] = 3, ["param1"] = 15, ["z"] = 3, ["name"] = "default:goldblock"}, {["x"] = 8, ["meta"] = {["fields"] = {}, ["inventory"] = {}}, ["param2"] = 0, ["y"] = 3, ["param1"] = 15, ["z"] = 4, ["name"] = "default:goldblock"}, {["x"] = 8, ["meta"] = {["fields"] = {}, ["inventory"] = {}}, ["param2"] = 0, ["y"] = 3, ["param1"] = 15, ["z"] = 5, ["name"] = "default:goldblock"}, {["x"] = 8, ["meta"] = {["fields"] = {}, ["inventory"] = {}}, ["param2"] = 0, ["y"] = 3, ["param1"] = 15, ["z"] = 6, ["name"] = "default:goldblock"}, {["x"] = 8, ["meta"] = {["fields"] = {}, ["inventory"] = {}}, ["param2"] = 0, ["y"] = 4, ["param1"] = 15, ["z"] = 2, ["name"] = "default:goldblock"}, {["x"] = 8, ["meta"] = {["fields"] = {}, ["inventory"] = {}}, ["param2"] = 0, ["y"] = 4, ["param1"] = 15, ["z"] = 3, ["name"] = "default:goldblock"}, {["x"] = 8, ["meta"] = {["fields"] = {}, ["inventory"] = {}}, ["param2"] = 0, ["y"] = 4, ["param1"] = 15, ["z"] = 4, ["name"] = "default:goldblock"}, {["x"] = 8, ["meta"] = {["fields"] = {}, ["inventory"] = {}}, ["param2"] = 0, ["y"] = 4, ["param1"] = 15, ["z"] = 5, ["name"] = "default:goldblock"}, {["x"] = 8, ["meta"] = {["fields"] = {}, ["inventory"] = {}}, ["param2"] = 0, ["y"] = 4, ["param1"] = 15, ["z"] = 6, ["name"] = "default:goldblock"}, {["x"] = 8, ["meta"] = {["fields"] = {}, ["inventory"] = {}}, ["param2"] = 0, ["y"] = 5, ["param1"] = 15, ["z"] = 2, ["name"] = "default:goldblock"}, {["x"] = 8, ["meta"] = {["fields"] = {}, ["inventory"] = {}}, ["param2"] = 0, ["y"] = 5, ["param1"] = 15, ["z"] = 3, ["name"] = "default:goldblock"}, {["x"] = 8, ["meta"] = {["fields"] = {}, ["inventory"] = {}}, ["param2"] = 0, ["y"] = 5, ["param1"] = 15, ["z"] = 4, ["name"] = "default:goldblock"}, {["x"] = 8, ["meta"] = {["fields"] = {}, ["inventory"] = {}}, ["param2"] = 0, ["y"] = 5, ["param1"] = 15, ["z"] = 5, ["name"] = "default:goldblock"}, {["x"] = 8, ["meta"] = {["fields"] = {}, ["inventory"] = {}}, ["param2"] = 0, ["y"] = 5, ["param1"] = 15, ["z"] = 6, ["name"] = "default:goldblock"}, {["x"] = 8, ["meta"] = {["fields"] = {}, ["inventory"] = {}}, ["param2"] = 0, ["y"] = 6, ["param1"] = 15, ["z"] = 2, ["name"] = "default:goldblock"}, {["x"] = 8, ["meta"] = {["fields"] = {}, ["inventory"] = {}}, ["param2"] = 0, ["y"] = 6, ["param1"] = 15, ["z"] = 3, ["name"] = "default:goldblock"}, {["x"] = 8, ["meta"] = {["fields"] = {}, ["inventory"] = {}}, ["param2"] = 0, ["y"] = 6, ["param1"] = 15, ["z"] = 4, ["name"] = "default:goldblock"}, {["x"] = 8, ["meta"] = {["fields"] = {}, ["inventory"] = {}}, ["param2"] = 0, ["y"] = 6, ["param1"] = 15, ["z"] = 5, ["name"] = "default:goldblock"}, {["x"] = 8, ["meta"] = {["fields"] = {}, ["inventory"] = {}}, ["param2"] = 0, ["y"] = 6, ["param1"] = 15, ["z"] = 6, ["name"] = "default:goldblock"}, {["x"] = 9, ["meta"] = {["fields"] = {}, ["inventory"] = {}}, ["param2"] = 0, ["y"] = 0, ["param1"] = 15, ["z"] = 2, ["name"] = "default:goldblock"}, {["x"] = 9, ["meta"] = {["fields"] = {}, ["inventory"] = {}}, ["param2"] = 0, ["y"] = 0, ["param1"] = 15, ["z"] = 3, ["name"] = "default:goldblock"}, {["x"] = 9, ["meta"] = {["fields"] = {}, ["inventory"] = {}}, ["param2"] = 0, ["y"] = 0, ["param1"] = 15, ["z"] = 4, ["name"] = "default:goldblock"}, {["x"] = 9, ["meta"] = {["fields"] = {}, ["inventory"] = {}}, ["param2"] = 0, ["y"] = 0, ["param1"] = 15, ["z"] = 5, ["name"] = "default:goldblock"}, {["x"] = 9, ["meta"] = {["fields"] = {}, ["inventory"] = {}}, ["param2"] = 0, ["y"] = 0, ["param1"] = 15, ["z"] = 6, ["name"] = "default:goldblock"}, {["x"] = 9, ["meta"] = {["fields"] = {}, ["inventory"] = {}}, ["param2"] = 0, ["y"] = 1, ["param1"] = 15, ["z"] = 2, ["name"] = "default:goldblock"}, {["x"] = 9, ["meta"] = {["fields"] = {}, ["inventory"] = {}}, ["param2"] = 0, ["y"] = 1, ["param1"] = 15, ["z"] = 3, ["name"] = "default:goldblock"}, {["x"] = 9, ["meta"] = {["fields"] = {}, ["inventory"] = {}}, ["param2"] = 0, ["y"] = 1, ["param1"] = 15, ["z"] = 4, ["name"] = "default:goldblock"}, {["x"] = 9, ["meta"] = {["fields"] = {}, ["inventory"] = {}}, ["param2"] = 0, ["y"] = 1, ["param1"] = 15, ["z"] = 5, ["name"] = "default:goldblock"}, {["x"] = 9, ["meta"] = {["fields"] = {}, ["inventory"] = {}}, ["param2"] = 0, ["y"] = 1, ["param1"] = 15, ["z"] = 6, ["name"] = "default:goldblock"}, {["x"] = 9, ["meta"] = {["fields"] = {}, ["inventory"] = {}}, ["param2"] = 0, ["y"] = 2, ["param1"] = 15, ["z"] = 2, ["name"] = "default:goldblock"}, {["x"] = 9, ["meta"] = {["fields"] = {}, ["inventory"] = {}}, ["param2"] = 0, ["y"] = 2, ["param1"] = 15, ["z"] = 3, ["name"] = "default:goldblock"}, {["x"] = 9, ["meta"] = {["fields"] = {}, ["inventory"] = {}}, ["param2"] = 0, ["y"] = 2, ["param1"] = 15, ["z"] = 4, ["name"] = "default:goldblock"}, {["x"] = 9, ["meta"] = {["fields"] = {}, ["inventory"] = {}}, ["param2"] = 0, ["y"] = 2, ["param1"] = 15, ["z"] = 5, ["name"] = "default:goldblock"}, {["x"] = 9, ["meta"] = {["fields"] = {}, ["inventory"] = {}}, ["param2"] = 0, ["y"] = 2, ["param1"] = 15, ["z"] = 6, ["name"] = "default:goldblock"}, {["x"] = 9, ["meta"] = {["fields"] = {}, ["inventory"] = {}}, ["param2"] = 0, ["y"] = 3, ["param1"] = 15, ["z"] = 2, ["name"] = "default:goldblock"}, {["x"] = 9, ["meta"] = {["fields"] = {}, ["inventory"] = {}}, ["param2"] = 0, ["y"] = 3, ["param1"] = 15, ["z"] = 3, ["name"] = "default:goldblock"}, {["x"] = 9, ["meta"] = {["fields"] = {}, ["inventory"] = {}}, ["param2"] = 0, ["y"] = 3, ["param1"] = 15, ["z"] = 4, ["name"] = "default:goldblock"}, {["x"] = 9, ["meta"] = {["fields"] = {}, ["inventory"] = {}}, ["param2"] = 0, ["y"] = 3, ["param1"] = 15, ["z"] = 5, ["name"] = "default:goldblock"}, {["x"] = 9, ["meta"] = {["fields"] = {}, ["inventory"] = {}}, ["param2"] = 0, ["y"] = 3, ["param1"] = 15, ["z"] = 6, ["name"] = "default:goldblock"}, {["x"] = 9, ["meta"] = {["fields"] = {}, ["inventory"] = {}}, ["param2"] = 0, ["y"] = 4, ["param1"] = 15, ["z"] = 2, ["name"] = "default:goldblock"}, {["x"] = 9, ["meta"] = {["fields"] = {}, ["inventory"] = {}}, ["param2"] = 0, ["y"] = 4, ["param1"] = 15, ["z"] = 3, ["name"] = "default:goldblock"}, {["x"] = 9, ["meta"] = {["fields"] = {}, ["inventory"] = {}}, ["param2"] = 0, ["y"] = 4, ["param1"] = 15, ["z"] = 4, ["name"] = "default:goldblock"}, {["x"] = 9, ["meta"] = {["fields"] = {}, ["inventory"] = {}}, ["param2"] = 0, ["y"] = 4, ["param1"] = 15, ["z"] = 5, ["name"] = "default:goldblock"}, {["x"] = 9, ["meta"] = {["fields"] = {}, ["inventory"] = {}}, ["param2"] = 0, ["y"] = 4, ["param1"] = 15, ["z"] = 6, ["name"] = "default:goldblock"}, {["x"] = 9, ["meta"] = {["fields"] = {}, ["inventory"] = {}}, ["param2"] = 0, ["y"] = 5, ["param1"] = 15, ["z"] = 2, ["name"] = "default:goldblock"}, {["x"] = 9, ["meta"] = {["fields"] = {}, ["inventory"] = {}}, ["param2"] = 0, ["y"] = 5, ["param1"] = 15, ["z"] = 3, ["name"] = "default:goldblock"}, {["x"] = 9, ["meta"] = {["fields"] = {}, ["inventory"] = {}}, ["param2"] = 0, ["y"] = 5, ["param1"] = 15, ["z"] = 4, ["name"] = "default:goldblock"}, {["x"] = 9, ["meta"] = {["fields"] = {}, ["inventory"] = {}}, ["param2"] = 0, ["y"] = 5, ["param1"] = 15, ["z"] = 5, ["name"] = "default:goldblock"}, {["x"] = 9, ["meta"] = {["fields"] = {}, ["inventory"] = {}}, ["param2"] = 0, ["y"] = 5, ["param1"] = 15, ["z"] = 6, ["name"] = "default:goldblock"}, {["x"] = 9, ["meta"] = {["fields"] = {}, ["inventory"] = {}}, ["param2"] = 0, ["y"] = 6, ["param1"] = 15, ["z"] = 2, ["name"] = "default:goldblock"}, {["x"] = 9, ["meta"] = {["fields"] = {}, ["inventory"] = {}}, ["param2"] = 0, ["y"] = 6, ["param1"] = 15, ["z"] = 3, ["name"] = "default:goldblock"}, {["x"] = 9, ["meta"] = {["fields"] = {}, ["inventory"] = {}}, ["param2"] = 0, ["y"] = 6, ["param1"] = 15, ["z"] = 4, ["name"] = "default:goldblock"}, {["x"] = 9, ["meta"] = {["fields"] = {}, ["inventory"] = {}}, ["param2"] = 0, ["y"] = 6, ["param1"] = 15, ["z"] = 5, ["name"] = "default:goldblock"}, {["x"] = 9, ["meta"] = {["fields"] = {}, ["inventory"] = {}}, ["param2"] = 0, ["y"] = 6, ["param1"] = 15, ["z"] = 6, ["name"] = "default:goldblock"}}