return {{["x"] = 18, ["meta"] = {["fields"] = {}, ["inventory"] = {}}, ["param2"] = 0, ["y"] = 0, ["param1"] = 15, ["z"] = 1, ["name"] = "default:diamondblock"}, {["x"] = 18, ["meta"] = {["fields"] = {}, ["inventory"] = {}}, ["param2"] = 0, ["y"] = 0, ["param1"] = 15, ["z"] = 2, ["name"] = "default:diamondblock"}, {["x"] = 18, ["meta"] = {["fields"] = {}, ["inventory"] = {}}, ["param2"] = 0, ["y"] = 0, ["param1"] = 15, ["z"] = 3, ["name"] = "default:diamondblock"}, {["x"] = 18, ["meta"] = {["fields"] = {}, ["inventory"] = {}}, ["param2"] = 0, ["y"] = 0, ["param1"] = 15, ["z"] = 4, ["name"] = "default:diamondblock"}, {["x"] = 18, ["meta"] = {["fields"] = {}, ["inventory"] = {}}, ["param2"] = 0, ["y"] = 0, ["param1"] = 15, ["z"] = 5, ["name"] = "default:diamondblock"}, {["x"] = 18, ["meta"] = {["fields"] = {}, ["inventory"] = {}}, ["param2"] = 0, ["y"] = 1, ["param1"] = 15, ["z"] = 1, ["name"] = "default:diamondblock"}, {["x"] = 18, ["meta"] = {["fields"] = {}, ["inventory"] = {}}, ["param2"] = 0, ["y"] = 1, ["param1"] = 15, ["z"] = 2, ["name"] = "default:diamondblock"}, {["x"] = 18, ["meta"] = {["fields"] = {}, ["inventory"] = {}}, ["param2"] = 0, ["y"] = 1, ["param1"] = 15, ["z"] = 3, ["name"] = "default:diamondblock"}, {["x"] = 18, ["meta"] = {["fields"] = {}, ["inventory"] = {}}, ["param2"] = 0, ["y"] = 1, ["param1"] = 15, ["z"] = 4, ["name"] = "default:diamondblock"}, {["x"] = 18, ["meta"] = {["fields"] = {}, ["inventory"] = {}}, ["param2"] = 0, ["y"] = 1, ["param1"] = 15, ["z"] = 5, ["name"] = "default:diamondblock"}, {["x"] = 18, ["meta"] = {["fields"] = {}, ["inventory"] = {}}, ["param2"] = 0, ["y"] = 2, ["param1"] = 15, ["z"] = 1, ["name"] = "default:diamondblock"}, {["x"] = 18, ["meta"] = {["fields"] = {}, ["inventory"] = {}}, ["param2"] = 0, ["y"] = 2, ["param1"] = 15, ["z"] = 2, ["name"] = "default:diamondblock"}, {["x"] = 18, ["meta"] = {["fields"] = {}, ["inventory"] = {}}, ["param2"] = 0, ["y"] = 2, ["param1"] = 15, ["z"] = 3, ["name"] = "default:diamondblock"}, {["x"] = 18, ["meta"] = {["fields"] = {}, ["inventory"] = {}}, ["param2"] = 0, ["y"] = 2, ["param1"] = 15, ["z"] = 4, ["name"] = "default:diamondblock"}, {["x"] = 18, ["meta"] = {["fields"] = {}, ["inventory"] = {}}, ["param2"] = 0, ["y"] = 2, ["param1"] = 15, ["z"] = 5, ["name"] = "default:diamondblock"}, {["x"] = 18, ["meta"] = {["fields"] = {}, ["inventory"] = {}}, ["param2"] = 0, ["y"] = 3, ["param1"] = 15, ["z"] = 1, ["name"] = "default:diamondblock"}, {["x"] = 18, ["meta"] = {["fields"] = {}, ["inventory"] = {}}, ["param2"] = 0, ["y"] = 3, ["param1"] = 15, ["z"] = 2, ["name"] = "default:diamondblock"}, {["x"] = 18, ["meta"] = {["fields"] = {}, ["inventory"] = {}}, ["param2"] = 0, ["y"] = 3, ["param1"] = 15, ["z"] = 3, ["name"] = "default:diamondblock"}, {["x"] = 18, ["meta"] = {["fields"] = {}, ["inventory"] = {}}, ["param2"] = 0, ["y"] = 3, ["param1"] = 15, ["z"] = 4, ["name"] = "default:diamondblock"}, {["x"] = 18, ["meta"] = {["fields"] = {}, ["inventory"] = {}}, ["param2"] = 0, ["y"] = 3, ["param1"] = 15, ["z"] = 5, ["name"] = "default:diamondblock"}, {["x"] = 18, ["meta"] = {["fields"] = {}, ["inventory"] = {}}, ["param2"] = 0, ["y"] = 4, ["param1"] = 15, ["z"] = 1, ["name"] = "default:diamondblock"}, {["x"] = 18, ["meta"] = {["fields"] = {}, ["inventory"] = {}}, ["param2"] = 0, ["y"] = 4, ["param1"] = 15, ["z"] = 2, ["name"] = "default:diamondblock"}, {["x"] = 18, ["meta"] = {["fields"] = {}, ["inventory"] = {}}, ["param2"] = 0, ["y"] = 4, ["param1"] = 15, ["z"] = 3, ["name"] = "default:diamondblock"}, {["x"] = 18, ["meta"] = {["fields"] = {}, ["inventory"] = {}}, ["param2"] = 0, ["y"] = 4, ["param1"] = 15, ["z"] = 4, ["name"] = "default:diamondblock"}, {["x"] = 18, ["meta"] = {["fields"] = {}, ["inventory"] = {}}, ["param2"] = 0, ["y"] = 4, ["param1"] = 15, ["z"] = 5, ["name"] = "default:diamondblock"}, {["x"] = 18, ["meta"] = {["fields"] = {}, ["inventory"] = {}}, ["param2"] = 0, ["y"] = 5, ["param1"] = 15, ["z"] = 1, ["name"] = "default:diamondblock"}, {["x"] = 18, ["meta"] = {["fields"] = {}, ["inventory"] = {}}, ["param2"] = 0, ["y"] = 5, ["param1"] = 15, ["z"] = 2, ["name"] = "default:diamondblock"}, {["x"] = 18, ["meta"] = {["fields"] = {}, ["inventory"] = {}}, ["param2"] = 0, ["y"] = 5, ["param1"] = 15, ["z"] = 3, ["name"] = "default:diamondblock"}, {["x"] = 18, ["meta"] = {["fields"] = {}, ["inventory"] = {}}, ["param2"] = 0, ["y"] = 5, ["param1"] = 15, ["z"] = 4, ["name"] = "default:diamondblock"}, {["x"] = 18, ["meta"] = {["fields"] = {}, ["inventory"] = {}}, ["param2"] = 0, ["y"] = 5, ["param1"] = 15, ["z"] = 5, ["name"] = "default:diamondblock"}, {["x"] = 18, ["meta"] = {["fields"] = {}, ["inventory"] = {}}, ["param2"] = 0, ["y"] = 6, ["param1"] = 15, ["z"] = 1, ["name"] = "default:diamondblock"}, {["x"] = 18, ["meta"] = {["fields"] = {}, ["inventory"] = {}}, ["param2"] = 0, ["y"] = 6, ["param1"] = 15, ["z"] = 2, ["name"] = "default:diamondblock"}, {["x"] = 18, ["meta"] = {["fields"] = {}, ["inventory"] = {}}, ["param2"] = 0, ["y"] = 6, ["param1"] = 15, ["z"] = 3, ["name"] = "default:diamondblock"}, {["x"] = 18, ["meta"] = {["fields"] = {}, ["inventory"] = {}}, ["param2"] = 0, ["y"] = 6, ["param1"] = 15, ["z"] = 4, ["name"] = "default:diamondblock"}, {["x"] = 18, ["meta"] = {["fields"] = {}, ["inventory"] = {}}, ["param2"] = 0, ["y"] = 6, ["param1"] = 15, ["z"] = 5, ["name"] = "default:diamondblock"}, {["x"] = 18, ["meta"] = {["fields"] = {}, ["inventory"] = {}}, ["param2"] = 0, ["y"] = 7, ["param1"] = 15, ["z"] = 1, ["name"] = "default:diamondblock"}, {["x"] = 18, ["meta"] = {["fields"] = {}, ["inventory"] = {}}, ["param2"] = 0, ["y"] = 7, ["param1"] = 15, ["z"] = 2, ["name"] = "default:diamondblock"}, {["x"] = 18, ["meta"] = {["fields"] = {}, ["inventory"] = {}}, ["param2"] = 0, ["y"] = 7, ["param1"] = 15, ["z"] = 3, ["name"] = "default:diamondblock"}, {["x"] = 18, ["meta"] = {["fields"] = {}, ["inventory"] = {}}, ["param2"] = 0, ["y"] = 7, ["param1"] = 15, ["z"] = 4, ["name"] = "default:diamondblock"}, {["x"] = 18, ["meta"] = {["fields"] = {}, ["inventory"] = {}}, ["param2"] = 0, ["y"] = 7, ["param1"] = 15, ["z"] = 5, ["name"] = "default:diamondblock"}, {["x"] = 19, ["meta"] = {["fields"] = {}, ["inventory"] = {}}, ["param2"] = 0, ["y"] = 0, ["param1"] = 15, ["z"] = 1, ["name"] = "default:diamondblock"}, {["x"] = 19, ["meta"] = {["fields"] = {}, ["inventory"] = {}}, ["param2"] = 0, ["y"] = 0, ["param1"] = 15, ["z"] = 2, ["name"] = "default:diamondblock"}, {["x"] = 19, ["meta"] = {["fields"] = {}, ["inventory"] = {}}, ["param2"] = 0, ["y"] = 0, ["param1"] = 15, ["z"] = 3, ["name"] = "default:diamondblock"}, {["x"] = 19, ["meta"] = {["fields"] = {}, ["inventory"] = {}}, ["param2"] = 0, ["y"] = 0, ["param1"] = 15, ["z"] = 4, ["name"] = "default:diamondblock"}, {["x"] = 19, ["meta"] = {["fields"] = {}, ["inventory"] = {}}, ["param2"] = 0, ["y"] = 0, ["param1"] = 15, ["z"] = 5, ["name"] = "default:diamondblock"}, {["x"] = 19, ["meta"] = {["fields"] = {}, ["inventory"] = {}}, ["param2"] = 0, ["y"] = 1, ["param1"] = 15, ["z"] = 1, ["name"] = "default:diamondblock"}, {["x"] = 19, ["meta"] = {["fields"] = {}, ["inventory"] = {}}, ["param2"] = 0, ["y"] = 1, ["param1"] = 15, ["z"] = 2, ["name"] = "default:diamondblock"}, {["x"] = 19, ["meta"] = {["fields"] = {}, ["inventory"] = {}}, ["param2"] = 0, ["y"] = 1, ["param1"] = 15, ["z"] = 3, ["name"] = "default:diamondblock"}, {["x"] = 19, ["meta"] = {["fields"] = {}, ["inventory"] = {}}, ["param2"] = 0, ["y"] = 1, ["param1"] = 15, ["z"] = 4, ["name"] = "default:diamondblock"}, {["x"] = 19, ["meta"] = {["fields"] = {}, ["inventory"] = {}}, ["param2"] = 0, ["y"] = 1, ["param1"] = 15, ["z"] = 5, ["name"] = "default:diamondblock"}, {["x"] = 19, ["meta"] = {["fields"] = {}, ["inventory"] = {}}, ["param2"] = 0, ["y"] = 2, ["param1"] = 15, ["z"] = 1, ["name"] = "default:diamondblock"}, {["x"] = 19, ["meta"] = {["fields"] = {}, ["inventory"] = {}}, ["param2"] = 0, ["y"] = 2, ["param1"] = 15, ["z"] = 2, ["name"] = "default:diamondblock"}, {["x"] = 19, ["meta"] = {["fields"] = {}, ["inventory"] = {}}, ["param2"] = 0, ["y"] = 2, ["param1"] = 15, ["z"] = 3, ["name"] = "default:diamondblock"}, {["x"] = 19, ["meta"] = {["fields"] = {}, ["inventory"] = {}}, ["param2"] = 0, ["y"] = 2, ["param1"] = 15, ["z"] = 4, ["name"] = "default:diamondblock"}, {["x"] = 19, ["meta"] = {["fields"] = {}, ["inventory"] = {}}, ["param2"] = 0, ["y"] = 2, ["param1"] = 15, ["z"] = 5, ["name"] = "default:diamondblock"}, {["x"] = 19, ["meta"] = {["fields"] = {}, ["inventory"] = {}}, ["param2"] = 0, ["y"] = 3, ["param1"] = 15, ["z"] = 1, ["name"] = "default:diamondblock"}, {["x"] = 19, ["meta"] = {["fields"] = {}, ["inventory"] = {}}, ["param2"] = 0, ["y"] = 3, ["param1"] = 15, ["z"] = 2, ["name"] = "default:diamondblock"}, {["x"] = 19, ["meta"] = {["fields"] = {}, ["inventory"] = {}}, ["param2"] = 0, ["y"] = 3, ["param1"] = 15, ["z"] = 3, ["name"] = "default:diamondblock"}, {["x"] = 19, ["meta"] = {["fields"] = {}, ["inventory"] = {}}, ["param2"] = 0, ["y"] = 3, ["param1"] = 15, ["z"] = 4, ["name"] = "default:diamondblock"}, {["x"] = 19, ["meta"] = {["fields"] = {}, ["inventory"] = {}}, ["param2"] = 0, ["y"] = 3, ["param1"] = 15, ["z"] = 5, ["name"] = "default:diamondblock"}, {["x"] = 19, ["meta"] = {["fields"] = {}, ["inventory"] = {}}, ["param2"] = 0, ["y"] = 4, ["param1"] = 15, ["z"] = 1, ["name"] = "default:diamondblock"}, {["x"] = 19, ["meta"] = {["fields"] = {}, ["inventory"] = {}}, ["param2"] = 0, ["y"] = 4, ["param1"] = 15, ["z"] = 2, ["name"] = "default:diamondblock"}, {["x"] = 19, ["meta"] = {["fields"] = {}, ["inventory"] = {}}, ["param2"] = 0, ["y"] = 4, ["param1"] = 15, ["z"] = 3, ["name"] = "default:diamondblock"}, {["x"] = 19, ["meta"] = {["fields"] = {}, ["inventory"] = {}}, ["param2"] = 0, ["y"] = 4, ["param1"] = 15, ["z"] = 4, ["name"] = "default:diamondblock"}, {["x"] = 19, ["meta"] = {["fields"] = {}, ["inventory"] = {}}, ["param2"] = 0, ["y"] = 4, ["param1"] = 15, ["z"] = 5, ["name"] = "default:diamondblock"}, {["x"] = 19, ["meta"] = {["fields"] = {}, ["inventory"] = {}}, ["param2"] = 0, ["y"] = 5, ["param1"] = 15, ["z"] = 1, ["name"] = "default:diamondblock"}, {["x"] = 19, ["meta"] = {["fields"] = {}, ["inventory"] = {}}, ["param2"] = 0, ["y"] = 5, ["param1"] = 15, ["z"] = 2, ["name"] = "default:diamondblock"}, {["x"] = 19, ["meta"] = {["fields"] = {}, ["inventory"] = {}}, ["param2"] = 0, ["y"] = 5, ["param1"] = 15, ["z"] = 3, ["name"] = "default:diamondblock"}, {["x"] = 19, ["meta"] = {["fields"] = {}, ["inventory"] = {}}, ["param2"] = 0, ["y"] = 5, ["param1"] = 15, ["z"] = 4, ["name"] = "default:diamondblock"}, {["x"] = 19, ["meta"] = {["fields"] = {}, ["inventory"] = {}}, ["param2"] = 0, ["y"] = 5, ["param1"] = 15, ["z"] = 5, ["name"] = "default:diamondblock"}, {["x"] = 19, ["meta"] = {["fields"] = {}, ["inventory"] = {}}, ["param2"] = 0, ["y"] = 6, ["param1"] = 15, ["z"] = 1, ["name"] = "default:diamondblock"}, {["x"] = 19, ["meta"] = {["fields"] = {}, ["inventory"] = {}}, ["param2"] = 0, ["y"] = 6, ["param1"] = 15, ["z"] = 2, ["name"] = "default:diamondblock"}, {["x"] = 19, ["meta"] = {["fields"] = {}, ["inventory"] = {}}, ["param2"] = 0, ["y"] = 6, ["param1"] = 15, ["z"] = 3, ["name"] = "default:diamondblock"}, {["x"] = 19, ["meta"] = {["fields"] = {}, ["inventory"] = {}}, ["param2"] = 0, ["y"] = 6, ["param1"] = 15, ["z"] = 4, ["name"] = "default:diamondblock"}, {["x"] = 19, ["meta"] = {["fields"] = {}, ["inventory"] = {}}, ["param2"] = 0, ["y"] = 6, ["param1"] = 15, ["z"] = 5, ["name"] = "default:diamondblock"}, {["x"] = 19, ["meta"] = {["fields"] = {}, ["inventory"] = {}}, ["param2"] = 0, ["y"] = 7, ["param1"] = 15, ["z"] = 1, ["name"] = "default:diamondblock"}, {["x"] = 19, ["meta"] = {["fields"] = {}, ["inventory"] = {}}, ["param2"] = 0, ["y"] = 7, ["param1"] = 15, ["z"] = 2, ["name"] = "default:diamondblock"}, {["x"] = 19, ["meta"] = {["fields"] = {}, ["inventory"] = {}}, ["param2"] = 0, ["y"] = 7, ["param1"] = 15, ["z"] = 3, ["name"] = "default:diamondblock"}, {["x"] = 19, ["meta"] = {["fields"] = {}, ["inventory"] = {}}, ["param2"] = 0, ["y"] = 7, ["param1"] = 15, ["z"] = 4, ["name"] = "default:diamondblock"}, {["x"] = 19, ["meta"] = {["fields"] = {}, ["inventory"] = {}}, ["param2"] = 0, ["y"] = 7, ["param1"] = 15, ["z"] = 5, ["name"] = "default:diamondblock"}, {["x"] = 20, ["meta"] = {["fields"] = {}, ["inventory"] = {}}, ["param2"] = 0, ["y"] = 0, ["param1"] = 15, ["z"] = 1, ["name"] = "default:diamondblock"}, {["x"] = 20, ["meta"] = {["fields"] = {}, ["inventory"] = {}}, ["param2"] = 0, ["y"] = 0, ["param1"] = 15, ["z"] = 2, ["name"] = "default:diamondblock"}, {["x"] = 20, ["meta"] = {["fields"] = {}, ["inventory"] = {}}, ["param2"] = 0, ["y"] = 0, ["param1"] = 15, ["z"] = 3, ["name"] = "default:diamondblock"}, {["x"] = 20, ["meta"] = {["fields"] = {}, ["inventory"] = {}}, ["param2"] = 0, ["y"] = 0, ["param1"] = 15, ["z"] = 4, ["name"] = "default:diamondblock"}, {["x"] = 20, ["meta"] = {["fields"] = {}, ["inventory"] = {}}, ["param2"] = 0, ["y"] = 0, ["param1"] = 15, ["z"] = 5, ["name"] = "default:diamondblock"}, {["x"] = 20, ["meta"] = {["fields"] = {}, ["inventory"] = {}}, ["param2"] = 0, ["y"] = 1, ["param1"] = 15, ["z"] = 1, ["name"] = "default:diamondblock"}, {["x"] = 20, ["meta"] = {["fields"] = {}, ["inventory"] = {}}, ["param2"] = 0, ["y"] = 1, ["param1"] = 15, ["z"] = 2, ["name"] = "default:diamondblock"}, {["x"] = 20, ["meta"] = {["fields"] = {}, ["inventory"] = {}}, ["param2"] = 0, ["y"] = 1, ["param1"] = 15, ["z"] = 3, ["name"] = "default:diamondblock"}, {["x"] = 20, ["meta"] = {["fields"] = {}, ["inventory"] = {}}, ["param2"] = 0, ["y"] = 1, ["param1"] = 15, ["z"] = 4, ["name"] = "default:diamondblock"}, {["x"] = 20, ["meta"] = {["fields"] = {}, ["inventory"] = {}}, ["param2"] = 0, ["y"] = 1, ["param1"] = 15, ["z"] = 5, ["name"] = "default:diamondblock"}, {["x"] = 20, ["meta"] = {["fields"] = {}, ["inventory"] = {}}, ["param2"] = 0, ["y"] = 2, ["param1"] = 15, ["z"] = 1, ["name"] = "default:diamondblock"}, {["x"] = 20, ["meta"] = {["fields"] = {}, ["inventory"] = {}}, ["param2"] = 0, ["y"] = 2, ["param1"] = 15, ["z"] = 2, ["name"] = "default:diamondblock"}, {["x"] = 20, ["meta"] = {["fields"] = {}, ["inventory"] = {}}, ["param2"] = 0, ["y"] = 2, ["param1"] = 15, ["z"] = 3, ["name"] = "default:diamondblock"}, {["x"] = 20, ["meta"] = {["fields"] = {}, ["inventory"] = {}}, ["param2"] = 0, ["y"] = 2, ["param1"] = 15, ["z"] = 4, ["name"] = "default:diamondblock"}, {["x"] = 20, ["meta"] = {["fields"] = {}, ["inventory"] = {}}, ["param2"] = 0, ["y"] = 2, ["param1"] = 15, ["z"] = 5, ["name"] = "default:diamondblock"}, {["x"] = 20, ["meta"] = {["fields"] = {}, ["inventory"] = {}}, ["param2"] = 0, ["y"] = 3, ["param1"] = 15, ["z"] = 1, ["name"] = "default:diamondblock"}, {["x"] = 20, ["meta"] = {["fields"] = {}, ["inventory"] = {}}, ["param2"] = 0, ["y"] = 3, ["param1"] = 15, ["z"] = 2, ["name"] = "default:diamondblock"}, {["x"] = 20, ["meta"] = {["fields"] = {}, ["inventory"] = {}}, ["param2"] = 0, ["y"] = 3, ["param1"] = 15, ["z"] = 3, ["name"] = "default:diamondblock"}, {["x"] = 20, ["meta"] = {["fields"] = {}, ["inventory"] = {}}, ["param2"] = 0, ["y"] = 3, ["param1"] = 15, ["z"] = 4, ["name"] = "default:diamondblock"}, {["x"] = 20, ["meta"] = {["fields"] = {}, ["inventory"] = {}}, ["param2"] = 0, ["y"] = 3, ["param1"] = 15, ["z"] = 5, ["name"] = "default:diamondblock"}, {["x"] = 20, ["meta"] = {["fields"] = {}, ["inventory"] = {}}, ["param2"] = 0, ["y"] = 4, ["param1"] = 15, ["z"] = 1, ["name"] = "default:diamondblock"}, {["x"] = 20, ["meta"] = {["fields"] = {}, ["inventory"] = {}}, ["param2"] = 0, ["y"] = 4, ["param1"] = 15, ["z"] = 2, ["name"] = "default:diamondblock"}, {["x"] = 20, ["meta"] = {["fields"] = {}, ["inventory"] = {}}, ["param2"] = 0, ["y"] = 4, ["param1"] = 15, ["z"] = 3, ["name"] = "default:diamondblock"}, {["x"] = 20, ["meta"] = {["fields"] = {}, ["inventory"] = {}}, ["param2"] = 0, ["y"] = 4, ["param1"] = 15, ["z"] = 4, ["name"] = "default:diamondblock"}, {["x"] = 20, ["meta"] = {["fields"] = {}, ["inventory"] = {}}, ["param2"] = 0, ["y"] = 4, ["param1"] = 15, ["z"] = 5, ["name"] = "default:diamondblock"}, {["x"] = 20, ["meta"] = {["fields"] = {}, ["inventory"] = {}}, ["param2"] = 0, ["y"] = 5, ["param1"] = 15, ["z"] = 1, ["name"] = "default:diamondblock"}, {["x"] = 20, ["meta"] = {["fields"] = {}, ["inventory"] = {}}, ["param2"] = 0, ["y"] = 5, ["param1"] = 15, ["z"] = 2, ["name"] = "default:diamondblock"}, {["x"] = 20, ["meta"] = {["fields"] = {}, ["inventory"] = {}}, ["param2"] = 0, ["y"] = 5, ["param1"] = 15, ["z"] = 3, ["name"] = "default:diamondblock"}, {["x"] = 20, ["meta"] = {["fields"] = {}, ["inventory"] = {}}, ["param2"] = 0, ["y"] = 5, ["param1"] = 15, ["z"] = 4, ["name"] = "default:diamondblock"}, {["x"] = 20, ["meta"] = {["fields"] = {}, ["inventory"] = {}}, ["param2"] = 0, ["y"] = 5, ["param1"] = 15, ["z"] = 5, ["name"] = "default:diamondblock"}, {["x"] = 20, ["meta"] = {["fields"] = {}, ["inventory"] = {}}, ["param2"] = 0, ["y"] = 6, ["param1"] = 15, ["z"] = 1, ["name"] = "default:diamondblock"}, {["x"] = 20, ["meta"] = {["fields"] = {}, ["inventory"] = {}}, ["param2"] = 0, ["y"] = 6, ["param1"] = 15, ["z"] = 2, ["name"] = "default:diamondblock"}, {["x"] = 20, ["meta"] = {["fields"] = {}, ["inventory"] = {}}, ["param2"] = 0, ["y"] = 6, ["param1"] = 15, ["z"] = 3, ["name"] = "default:diamondblock"}, {["x"] = 20, ["meta"] = {["fields"] = {}, ["inventory"] = {}}, ["param2"] = 0, ["y"] = 6, ["param1"] = 15, ["z"] = 4, ["name"] = "default:diamondblock"}, {["x"] = 20, ["meta"] = {["fields"] = {}, ["inventory"] = {}}, ["param2"] = 0, ["y"] = 6, ["param1"] = 15, ["z"] = 5, ["name"] = "default:diamondblock"}, {["x"] = 20, ["meta"] = {["fields"] = {}, ["inventory"] = {}}, ["param2"] = 0, ["y"] = 7, ["param1"] = 15, ["z"] = 1, ["name"] = "default:diamondblock"}, {["x"] = 20, ["meta"] = {["fields"] = {}, ["inventory"] = {}}, ["param2"] = 0, ["y"] = 7, ["param1"] = 15, ["z"] = 2, ["name"] = "default:diamondblock"}, {["x"] = 20, ["meta"] = {["fields"] = {}, ["inventory"] = {}}, ["param2"] = 0, ["y"] = 7, ["param1"] = 15, ["z"] = 3, ["name"] = "default:diamondblock"}, {["x"] = 20, ["meta"] = {["fields"] = {}, ["inventory"] = {}}, ["param2"] = 0, ["y"] = 7, ["param1"] = 15, ["z"] = 4, ["name"] = "default:diamondblock"}, {["x"] = 20, ["meta"] = {["fields"] = {}, ["inventory"] = {}}, ["param2"] = 0, ["y"] = 7, ["param1"] = 15, ["z"] = 5, ["name"] = "default:diamondblock"}, {["x"] = 21, ["meta"] = {["fields"] = {}, ["inventory"] = {}}, ["param2"] = 0, ["y"] = 0, ["param1"] = 15, ["z"] = 1, ["name"] = "default:diamondblock"}, {["x"] = 21, ["meta"] = {["fields"] = {}, ["inventory"] = {}}, ["param2"] = 0, ["y"] = 0, ["param1"] = 15, ["z"] = 2, ["name"] = "default:diamondblock"}, {["x"] = 21, ["meta"] = {["fields"] = {}, ["inventory"] = {}}, ["param2"] = 0, ["y"] = 0, ["param1"] = 15, ["z"] = 3, ["name"] = "default:diamondblock"}, {["x"] = 21, ["meta"] = {["fields"] = {}, ["inventory"] = {}}, ["param2"] = 0, ["y"] = 0, ["param1"] = 15, ["z"] = 4, ["name"] = "default:diamondblock"}, {["x"] = 21, ["meta"] = {["fields"] = {}, ["inventory"] = {}}, ["param2"] = 0, ["y"] = 0, ["param1"] = 15, ["z"] = 5, ["name"] = "default:diamondblock"}, {["x"] = 21, ["meta"] = {["fields"] = {}, ["inventory"] = {}}, ["param2"] = 0, ["y"] = 1, ["param1"] = 15, ["z"] = 1, ["name"] = "default:diamondblock"}, {["x"] = 21, ["meta"] = {["fields"] = {}, ["inventory"] = {}}, ["param2"] = 0, ["y"] = 1, ["param1"] = 15, ["z"] = 2, ["name"] = "default:diamondblock"}, {["x"] = 21, ["meta"] = {["fields"] = {}, ["inventory"] = {}}, ["param2"] = 0, ["y"] = 1, ["param1"] = 15, ["z"] = 3, ["name"] = "default:diamondblock"}, {["x"] = 21, ["meta"] = {["fields"] = {}, ["inventory"] = {}}, ["param2"] = 0, ["y"] = 1, ["param1"] = 15, ["z"] = 4, ["name"] = "default:diamondblock"}, {["x"] = 21, ["meta"] = {["fields"] = {}, ["inventory"] = {}}, ["param2"] = 0, ["y"] = 1, ["param1"] = 15, ["z"] = 5, ["name"] = "default:diamondblock"}, {["x"] = 21, ["meta"] = {["fields"] = {}, ["inventory"] = {}}, ["param2"] = 0, ["y"] = 2, ["param1"] = 15, ["z"] = 1, ["name"] = "default:diamondblock"}, {["x"] = 21, ["meta"] = {["fields"] = {}, ["inventory"] = {}}, ["param2"] = 0, ["y"] = 2, ["param1"] = 15, ["z"] = 2, ["name"] = "default:diamondblock"}, {["x"] = 21, ["meta"] = {["fields"] = {}, ["inventory"] = {}}, ["param2"] = 0, ["y"] = 2, ["param1"] = 15, ["z"] = 3, ["name"] = "default:diamondblock"}, {["x"] = 21, ["meta"] = {["fields"] = {}, ["inventory"] = {}}, ["param2"] = 0, ["y"] = 2, ["param1"] = 15, ["z"] = 4, ["name"] = "default:diamondblock"}, {["x"] = 21, ["meta"] = {["fields"] = {}, ["inventory"] = {}}, ["param2"] = 0, ["y"] = 2, ["param1"] = 15, ["z"] = 5, ["name"] = "default:diamondblock"}, {["x"] = 21, ["meta"] = {["fields"] = {}, ["inventory"] = {}}, ["param2"] = 0, ["y"] = 3, ["param1"] = 15, ["z"] = 1, ["name"] = "default:diamondblock"}, {["x"] = 21, ["meta"] = {["fields"] = {}, ["inventory"] = {}}, ["param2"] = 0, ["y"] = 3, ["param1"] = 15, ["z"] = 2, ["name"] = "default:diamondblock"}, {["x"] = 21, ["meta"] = {["fields"] = {}, ["inventory"] = {}}, ["param2"] = 0, ["y"] = 3, ["param1"] = 15, ["z"] = 3, ["name"] = "default:diamondblock"}, {["x"] = 21, ["meta"] = {["fields"] = {}, ["inventory"] = {}}, ["param2"] = 0, ["y"] = 3, ["param1"] = 15, ["z"] = 4, ["name"] = "default:diamondblock"}, {["x"] = 21, ["meta"] = {["fields"] = {}, ["inventory"] = {}}, ["param2"] = 0, ["y"] = 3, ["param1"] = 15, ["z"] = 5, ["name"] = "default:diamondblock"}, {["x"] = 21, ["meta"] = {["fields"] = {}, ["inventory"] = {}}, ["param2"] = 0, ["y"] = 4, ["param1"] = 15, ["z"] = 1, ["name"] = "default:diamondblock"}, {["x"] = 21, ["meta"] = {["fields"] = {}, ["inventory"] = {}}, ["param2"] = 0, ["y"] = 4, ["param1"] = 15, ["z"] = 2, ["name"] = "default:diamondblock"}, {["x"] = 21, ["meta"] = {["fields"] = {}, ["inventory"] = {}}, ["param2"] = 0, ["y"] = 4, ["param1"] = 15, ["z"] = 3, ["name"] = "default:diamondblock"}, {["x"] = 21, ["meta"] = {["fields"] = {}, ["inventory"] = {}}, ["param2"] = 0, ["y"] = 4, ["param1"] = 15, ["z"] = 4, ["name"] = "default:diamondblock"}, {["x"] = 21, ["meta"] = {["fields"] = {}, ["inventory"] = {}}, ["param2"] = 0, ["y"] = 4, ["param1"] = 15, ["z"] = 5, ["name"] = "default:diamondblock"}, {["x"] = 21, ["meta"] = {["fields"] = {}, ["inventory"] = {}}, ["param2"] = 0, ["y"] = 5, ["param1"] = 15, ["z"] = 1, ["name"] = "default:diamondblock"}, {["x"] = 21, ["meta"] = {["fields"] = {}, ["inventory"] = {}}, ["param2"] = 0, ["y"] = 5, ["param1"] = 15, ["z"] = 2, ["name"] = "default:diamondblock"}, {["x"] = 21, ["meta"] = {["fields"] = {}, ["inventory"] = {}}, ["param2"] = 0, ["y"] = 5, ["param1"] = 15, ["z"] = 3, ["name"] = "default:diamondblock"}, {["x"] = 21, ["meta"] = {["fields"] = {}, ["inventory"] = {}}, ["param2"] = 0, ["y"] = 5, ["param1"] = 15, ["z"] = 4, ["name"] = "default:diamondblock"}, {["x"] = 21, ["meta"] = {["fields"] = {}, ["inventory"] = {}}, ["param2"] = 0, ["y"] = 5, ["param1"] = 15, ["z"] = 5, ["name"] = "default:diamondblock"}, {["x"] = 21, ["meta"] = {["fields"] = {}, ["inventory"] = {}}, ["param2"] = 0, ["y"] = 6, ["param1"] = 15, ["z"] = 1, ["name"] = "default:diamondblock"}, {["x"] = 21, ["meta"] = {["fields"] = {}, ["inventory"] = {}}, ["param2"] = 0, ["y"] = 6, ["param1"] = 15, ["z"] = 2, ["name"] = "default:diamondblock"}, {["x"] = 21, ["meta"] = {["fields"] = {}, ["inventory"] = {}}, ["param2"] = 0, ["y"] = 6, ["param1"] = 15, ["z"] = 3, ["name"] = "default:diamondblock"}, {["x"] = 21, ["meta"] = {["fields"] = {}, ["inventory"] = {}}, ["param2"] = 0, ["y"] = 6, ["param1"] = 15, ["z"] = 4, ["name"] = "default:diamondblock"}, {["x"] = 21, ["meta"] = {["fields"] = {}, ["inventory"] = {}}, ["param2"] = 0, ["y"] = 6, ["param1"] = 15, ["z"] = 5, ["name"] = "default:diamondblock"}, {["x"] = 21, ["meta"] = {["fields"] = {}, ["inventory"] = {}}, ["param2"] = 0, ["y"] = 7, ["param1"] = 15, ["z"] = 1, ["name"] = "default:diamondblock"}, {["x"] = 21, ["meta"] = {["fields"] = {}, ["inventory"] = {}}, ["param2"] = 0, ["y"] = 7, ["param1"] = 15, ["z"] = 2, ["name"] = "default:diamondblock"}, {["x"] = 21, ["meta"] = {["fields"] = {}, ["inventory"] = {}}, ["param2"] = 0, ["y"] = 7, ["param1"] = 15, ["z"] = 3, ["name"] = "default:diamondblock"}, {["x"] = 21, ["meta"] = {["fields"] = {}, ["inventory"] = {}}, ["param2"] = 0, ["y"] = 7, ["param1"] = 15, ["z"] = 4, ["name"] = "default:diamondblock"}, {["x"] = 21, ["meta"] = {["fields"] = {}, ["inventory"] = {}}, ["param2"] = 0, ["y"] = 7, ["param1"] = 15, ["z"] = 5, ["name"] = "default:diamondblock"}, {["x"] = 22, ["meta"] = {["fields"] = {}, ["inventory"] = {}}, ["param2"] = 0, ["y"] = 0, ["param1"] = 15, ["z"] = 1, ["name"] = "default:diamondblock"}, {["x"] = 22, ["meta"] = {["fields"] = {}, ["inventory"] = {}}, ["param2"] = 0, ["y"] = 0, ["param1"] = 15, ["z"] = 2, ["name"] = "default:diamondblock"}, {["x"] = 22, ["meta"] = {["fields"] = {}, ["inventory"] = {}}, ["param2"] = 0, ["y"] = 0, ["param1"] = 15, ["z"] = 3, ["name"] = "default:diamondblock"}, {["x"] = 22, ["meta"] = {["fields"] = {}, ["inventory"] = {}}, ["param2"] = 0, ["y"] = 0, ["param1"] = 15, ["z"] = 4, ["name"] = "default:diamondblock"}, {["x"] = 22, ["meta"] = {["fields"] = {}, ["inventory"] = {}}, ["param2"] = 0, ["y"] = 0, ["param1"] = 15, ["z"] = 5, ["name"] = "default:diamondblock"}, {["x"] = 22, ["meta"] = {["fields"] = {}, ["inventory"] = {}}, ["param2"] = 0, ["y"] = 1, ["param1"] = 15, ["z"] = 1, ["name"] = "default:diamondblock"}, {["x"] = 22, ["meta"] = {["fields"] = {}, ["inventory"] = {}}, ["param2"] = 0, ["y"] = 1, ["param1"] = 15, ["z"] = 2, ["name"] = "default:diamondblock"}, {["x"] = 22, ["meta"] = {["fields"] = {}, ["inventory"] = {}}, ["param2"] = 0, ["y"] = 1, ["param1"] = 15, ["z"] = 3, ["name"] = "default:diamondblock"}, {["x"] = 22, ["meta"] = {["fields"] = {}, ["inventory"] = {}}, ["param2"] = 0, ["y"] = 1, ["param1"] = 15, ["z"] = 4, ["name"] = "default:diamondblock"}, {["x"] = 22, ["meta"] = {["fields"] = {}, ["inventory"] = {}}, ["param2"] = 0, ["y"] = 1, ["param1"] = 15, ["z"] = 5, ["name"] = "default:diamondblock"}, {["x"] = 22, ["meta"] = {["fields"] = {}, ["inventory"] = {}}, ["param2"] = 0, ["y"] = 2, ["param1"] = 15, ["z"] = 1, ["name"] = "default:diamondblock"}, {["x"] = 22, ["meta"] = {["fields"] = {}, ["inventory"] = {}}, ["param2"] = 0, ["y"] = 2, ["param1"] = 15, ["z"] = 2, ["name"] = "default:diamondblock"}, {["x"] = 22, ["meta"] = {["fields"] = {}, ["inventory"] = {}}, ["param2"] = 0, ["y"] = 2, ["param1"] = 15, ["z"] = 3, ["name"] = "default:diamondblock"}, {["x"] = 22, ["meta"] = {["fields"] = {}, ["inventory"] = {}}, ["param2"] = 0, ["y"] = 2, ["param1"] = 15, ["z"] = 4, ["name"] = "default:diamondblock"}, {["x"] = 22, ["meta"] = {["fields"] = {}, ["inventory"] = {}}, ["param2"] = 0, ["y"] = 2, ["param1"] = 15, ["z"] = 5, ["name"] = "default:diamondblock"}, {["x"] = 22, ["meta"] = {["fields"] = {}, ["inventory"] = {}}, ["param2"] = 0, ["y"] = 3, ["param1"] = 15, ["z"] = 1, ["name"] = "default:diamondblock"}, {["x"] = 22, ["meta"] = {["fields"] = {}, ["inventory"] = {}}, ["param2"] = 0, ["y"] = 3, ["param1"] = 15, ["z"] = 2, ["name"] = "default:diamondblock"}, {["x"] = 22, ["meta"] = {["fields"] = {}, ["inventory"] = {}}, ["param2"] = 0, ["y"] = 3, ["param1"] = 15, ["z"] = 3, ["name"] = "default:diamondblock"}, {["x"] = 22, ["meta"] = {["fields"] = {}, ["inventory"] = {}}, ["param2"] = 0, ["y"] = 3, ["param1"] = 15, ["z"] = 4, ["name"] = "default:diamondblock"}, {["x"] = 22, ["meta"] = {["fields"] = {}, ["inventory"] = {}}, ["param2"] = 0, ["y"] = 3, ["param1"] = 15, ["z"] = 5, ["name"] = "default:diamondblock"}, {["x"] = 22, ["meta"] = {["fields"] = {}, ["inventory"] = {}}, ["param2"] = 0, ["y"] = 4, ["param1"] = 15, ["z"] = 1, ["name"] = "default:diamondblock"}, {["x"] = 22, ["meta"] = {["fields"] = {}, ["inventory"] = {}}, ["param2"] = 0, ["y"] = 4, ["param1"] = 15, ["z"] = 2, ["name"] = "default:diamondblock"}, {["x"] = 22, ["meta"] = {["fields"] = {}, ["inventory"] = {}}, ["param2"] = 0, ["y"] = 4, ["param1"] = 15, ["z"] = 3, ["name"] = "default:diamondblock"}, {["x"] = 22, ["meta"] = {["fields"] = {}, ["inventory"] = {}}, ["param2"] = 0, ["y"] = 4, ["param1"] = 15, ["z"] = 4, ["name"] = "default:diamondblock"}, {["x"] = 22, ["meta"] = {["fields"] = {}, ["inventory"] = {}}, ["param2"] = 0, ["y"] = 4, ["param1"] = 15, ["z"] = 5, ["name"] = "default:diamondblock"}, {["x"] = 22, ["meta"] = {["fields"] = {}, ["inventory"] = {}}, ["param2"] = 0, ["y"] = 5, ["param1"] = 15, ["z"] = 1, ["name"] = "default:diamondblock"}, {["x"] = 22, ["meta"] = {["fields"] = {}, ["inventory"] = {}}, ["param2"] = 0, ["y"] = 5, ["param1"] = 15, ["z"] = 2, ["name"] = "default:diamondblock"}, {["x"] = 22, ["meta"] = {["fields"] = {}, ["inventory"] = {}}, ["param2"] = 0, ["y"] = 5, ["param1"] = 15, ["z"] = 3, ["name"] = "default:diamondblock"}, {["x"] = 22, ["meta"] = {["fields"] = {}, ["inventory"] = {}}, ["param2"] = 0, ["y"] = 5, ["param1"] = 15, ["z"] = 4, ["name"] = "default:diamondblock"}, {["x"] = 22, ["meta"] = {["fields"] = {}, ["inventory"] = {}}, ["param2"] = 0, ["y"] = 5, ["param1"] = 15, ["z"] = 5, ["name"] = "default:diamondblock"}, {["x"] = 22, ["meta"] = {["fields"] = {}, ["inventory"] = {}}, ["param2"] = 0, ["y"] = 6, ["param1"] = 15, ["z"] = 1, ["name"] = "default:diamondblock"}, {["x"] = 22, ["meta"] = {["fields"] = {}, ["inventory"] = {}}, ["param2"] = 0, ["y"] = 6, ["param1"] = 15, ["z"] = 2, ["name"] = "default:diamondblock"}, {["x"] = 22, ["meta"] = {["fields"] = {}, ["inventory"] = {}}, ["param2"] = 0, ["y"] = 6, ["param1"] = 15, ["z"] = 3, ["name"] = "default:diamondblock"}, {["x"] = 22, ["meta"] = {["fields"] = {}, ["inventory"] = {}}, ["param2"] = 0, ["y"] = 6, ["param1"] = 15, ["z"] = 4, ["name"] = "default:diamondblock"}, {["x"] = 22, ["meta"] = {["fields"] = {}, ["inventory"] = {}}, ["param2"] = 0, ["y"] = 6, ["param1"] = 15, ["z"] = 5, ["name"] = "default:diamondblock"}, {["x"] = 22, ["meta"] = {["fields"] = {}, ["inventory"] = {}}, ["param2"] = 0, ["y"] = 7, ["param1"] = 15, ["z"] = 1, ["name"] = "default:diamondblock"}, {["x"] = 22, ["meta"] = {["fields"] = {}, ["inventory"] = {}}, ["param2"] = 0, ["y"] = 7, ["param1"] = 15, ["z"] = 2, ["name"] = "default:diamondblock"}, {["x"] = 22, ["meta"] = {["fields"] = {}, ["inventory"] = {}}, ["param2"] = 0, ["y"] = 7, ["param1"] = 15, ["z"] = 3, ["name"] = "default:diamondblock"}, {["x"] = 22, ["meta"] = {["fields"] = {}, ["inventory"] = {}}, ["param2"] = 0, ["y"] = 7, ["param1"] = 15, ["z"] = 4, ["name"] = "default:diamondblock"}, {["x"] = 22, ["meta"] = {["fields"] = {}, ["inventory"] = {}}, ["param2"] = 0, ["y"] = 7, ["param1"] = 15, ["z"] = 5, ["name"] = "default:diamondblock"}, {["x"] = 23, ["meta"] = {["fields"] = {}, ["inventory"] = {}}, ["param2"] = 0, ["y"] = 0, ["param1"] = 15, ["z"] = 1, ["name"] = "default:diamondblock"}, {["x"] = 23, ["meta"] = {["fields"] = {}, ["inventory"] = {}}, ["param2"] = 0, ["y"] = 0, ["param1"] = 15, ["z"] = 2, ["name"] = "default:diamondblock"}, {["x"] = 23, ["meta"] = {["fields"] = {}, ["inventory"] = {}}, ["param2"] = 0, ["y"] = 0, ["param1"] = 15, ["z"] = 3, ["name"] = "default:diamondblock"}, {["x"] = 23, ["meta"] = {["fields"] = {}, ["inventory"] = {}}, ["param2"] = 0, ["y"] = 0, ["param1"] = 15, ["z"] = 4, ["name"] = "default:diamondblock"}, {["x"] = 23, ["meta"] = {["fields"] = {}, ["inventory"] = {}}, ["param2"] = 0, ["y"] = 0, ["param1"] = 15, ["z"] = 5, ["name"] = "default:diamondblock"}, {["x"] = 23, ["meta"] = {["fields"] = {}, ["inventory"] = {}}, ["param2"] = 0, ["y"] = 1, ["param1"] = 15, ["z"] = 1, ["name"] = "default:diamondblock"}, {["x"] = 23, ["meta"] = {["fields"] = {}, ["inventory"] = {}}, ["param2"] = 0, ["y"] = 1, ["param1"] = 15, ["z"] = 2, ["name"] = "default:diamondblock"}, {["x"] = 23, ["meta"] = {["fields"] = {}, ["inventory"] = {}}, ["param2"] = 0, ["y"] = 1, ["param1"] = 15, ["z"] = 3, ["name"] = "default:diamondblock"}, {["x"] = 23, ["meta"] = {["fields"] = {}, ["inventory"] = {}}, ["param2"] = 0, ["y"] = 1, ["param1"] = 15, ["z"] = 4, ["name"] = "default:diamondblock"}, {["x"] = 23, ["meta"] = {["fields"] = {}, ["inventory"] = {}}, ["param2"] = 0, ["y"] = 1, ["param1"] = 15, ["z"] = 5, ["name"] = "default:diamondblock"}, {["x"] = 23, ["meta"] = {["fields"] = {}, ["inventory"] = {}}, ["param2"] = 0, ["y"] = 2, ["param1"] = 15, ["z"] = 1, ["name"] = "default:diamondblock"}, {["x"] = 23, ["meta"] = {["fields"] = {}, ["inventory"] = {}}, ["param2"] = 0, ["y"] = 2, ["param1"] = 15, ["z"] = 2, ["name"] = "default:diamondblock"}, {["x"] = 23, ["meta"] = {["fields"] = {}, ["inventory"] = {}}, ["param2"] = 0, ["y"] = 2, ["param1"] = 15, ["z"] = 3, ["name"] = "default:diamondblock"}, {["x"] = 23, ["meta"] = {["fields"] = {}, ["inventory"] = {}}, ["param2"] = 0, ["y"] = 2, ["param1"] = 15, ["z"] = 4, ["name"] = "default:diamondblock"}, {["x"] = 23, ["meta"] = {["fields"] = {}, ["inventory"] = {}}, ["param2"] = 0, ["y"] = 2, ["param1"] = 15, ["z"] = 5, ["name"] = "default:diamondblock"}, {["x"] = 23, ["meta"] = {["fields"] = {}, ["inventory"] = {}}, ["param2"] = 0, ["y"] = 3, ["param1"] = 15, ["z"] = 1, ["name"] = "default:diamondblock"}, {["x"] = 23, ["meta"] = {["fields"] = {}, ["inventory"] = {}}, ["param2"] = 0, ["y"] = 3, ["param1"] = 15, ["z"] = 2, ["name"] = "default:diamondblock"}, {["x"] = 23, ["meta"] = {["fields"] = {}, ["inventory"] = {}}, ["param2"] = 0, ["y"] = 3, ["param1"] = 15, ["z"] = 3, ["name"] = "default:diamondblock"}, {["x"] = 23, ["meta"] = {["fields"] = {}, ["inventory"] = {}}, ["param2"] = 0, ["y"] = 3, ["param1"] = 15, ["z"] = 4, ["name"] = "default:diamondblock"}, {["x"] = 23, ["meta"] = {["fields"] = {}, ["inventory"] = {}}, ["param2"] = 0, ["y"] = 3, ["param1"] = 15, ["z"] = 5, ["name"] = "default:diamondblock"}, {["x"] = 23, ["meta"] = {["fields"] = {}, ["inventory"] = {}}, ["param2"] = 0, ["y"] = 4, ["param1"] = 15, ["z"] = 1, ["name"] = "default:diamondblock"}, {["x"] = 23, ["meta"] = {["fields"] = {}, ["inventory"] = {}}, ["param2"] = 0, ["y"] = 4, ["param1"] = 15, ["z"] = 2, ["name"] = "default:diamondblock"}, {["x"] = 23, ["meta"] = {["fields"] = {}, ["inventory"] = {}}, ["param2"] = 0, ["y"] = 4, ["param1"] = 15, ["z"] = 3, ["name"] = "default:diamondblock"}, {["x"] = 23, ["meta"] = {["fields"] = {}, ["inventory"] = {}}, ["param2"] = 0, ["y"] = 4, ["param1"] = 15, ["z"] = 4, ["name"] = "default:diamondblock"}, {["x"] = 23, ["meta"] = {["fields"] = {}, ["inventory"] = {}}, ["param2"] = 0, ["y"] = 4, ["param1"] = 15, ["z"] = 5, ["name"] = "default:diamondblock"}, {["x"] = 23, ["meta"] = {["fields"] = {}, ["inventory"] = {}}, ["param2"] = 0, ["y"] = 5, ["param1"] = 15, ["z"] = 1, ["name"] = "default:diamondblock"}, {["x"] = 23, ["meta"] = {["fields"] = {}, ["inventory"] = {}}, ["param2"] = 0, ["y"] = 5, ["param1"] = 15, ["z"] = 2, ["name"] = "default:diamondblock"}, {["x"] = 23, ["meta"] = {["fields"] = {}, ["inventory"] = {}}, ["param2"] = 0, ["y"] = 5, ["param1"] = 15, ["z"] = 3, ["name"] = "default:diamondblock"}, {["x"] = 23, ["meta"] = {["fields"] = {}, ["inventory"] = {}}, ["param2"] = 0, ["y"] = 5, ["param1"] = 15, ["z"] = 4, ["name"] = "default:diamondblock"}, {["x"] = 23, ["meta"] = {["fields"] = {}, ["inventory"] = {}}, ["param2"] = 0, ["y"] = 5, ["param1"] = 15, ["z"] = 5, ["name"] = "default:diamondblock"}, {["x"] = 23, ["meta"] = {["fields"] = {}, ["inventory"] = {}}, ["param2"] = 0, ["y"] = 6, ["param1"] = 15, ["z"] = 1, ["name"] = "default:diamondblock"}, {["x"] = 23, ["meta"] = {["fields"] = {}, ["inventory"] = {}}, ["param2"] = 0, ["y"] = 6, ["param1"] = 15, ["z"] = 2, ["name"] = "default:diamondblock"}, {["x"] = 23, ["meta"] = {["fields"] = {}, ["inventory"] = {}}, ["param2"] = 0, ["y"] = 6, ["param1"] = 15, ["z"] = 3, ["name"] = "default:diamondblock"}, {["x"] = 23, ["meta"] = {["fields"] = {}, ["inventory"] = {}}, ["param2"] = 0, ["y"] = 6, ["param1"] = 15, ["z"] = 4, ["name"] = "default:diamondblock"}, {["x"] = 23, ["meta"] = {["fields"] = {}, ["inventory"] = {}}, ["param2"] = 0, ["y"] = 6, ["param1"] = 15, ["z"] = 5, ["name"] = "default:diamondblock"}, {["x"] = 23, ["meta"] = {["fields"] = {}, ["inventory"] = {}}, ["param2"] = 0, ["y"] = 7, ["param1"] = 15, ["z"] = 1, ["name"] = "default:diamondblock"}, {["x"] = 23, ["meta"] = {["fields"] = {}, ["inventory"] = {}}, ["param2"] = 0, ["y"] = 7, ["param1"] = 15, ["z"] = 2, ["name"] = "default:diamondblock"}, {["x"] = 23, ["meta"] = {["fields"] = {}, ["inventory"] = {}}, ["param2"] = 0, ["y"] = 7, ["param1"] = 15, ["z"] = 3, ["name"] = "default:diamondblock"}, {["x"] = 23, ["meta"] = {["fields"] = {}, ["inventory"] = {}}, ["param2"] = 0, ["y"] = 7, ["param1"] = 15, ["z"] = 4, ["name"] = "default:diamondblock"}, {["x"] = 23, ["meta"] = {["fields"] = {}, ["inventory"] = {}}, ["param2"] = 0, ["y"] = 7, ["param1"] = 15, ["z"] = 5, ["name"] = "default:diamondblock"}, {["x"] = 24, ["meta"] = {["fields"] = {}, ["inventory"] = {}}, ["param2"] = 0, ["y"] = 0, ["param1"] = 15, ["z"] = 1, ["name"] = "default:diamondblock"}, {["x"] = 24, ["meta"] = {["fields"] = {}, ["inventory"] = {}}, ["param2"] = 0, ["y"] = 0, ["param1"] = 15, ["z"] = 2, ["name"] = "default:diamondblock"}, {["x"] = 24, ["meta"] = {["fields"] = {}, ["inventory"] = {}}, ["param2"] = 0, ["y"] = 0, ["param1"] = 15, ["z"] = 3, ["name"] = "default:diamondblock"}, {["x"] = 24, ["meta"] = {["fields"] = {}, ["inventory"] = {}}, ["param2"] = 0, ["y"] = 0, ["param1"] = 15, ["z"] = 4, ["name"] = "default:diamondblock"}, {["x"] = 24, ["meta"] = {["fields"] = {}, ["inventory"] = {}}, ["param2"] = 0, ["y"] = 0, ["param1"] = 15, ["z"] = 5, ["name"] = "default:diamondblock"}, {["x"] = 24, ["meta"] = {["fields"] = {}, ["inventory"] = {}}, ["param2"] = 0, ["y"] = 1, ["param1"] = 15, ["z"] = 1, ["name"] = "default:diamondblock"}, {["x"] = 24, ["meta"] = {["fields"] = {}, ["inventory"] = {}}, ["param2"] = 0, ["y"] = 1, ["param1"] = 15, ["z"] = 2, ["name"] = "default:diamondblock"}, {["x"] = 24, ["meta"] = {["fields"] = {}, ["inventory"] = {}}, ["param2"] = 0, ["y"] = 1, ["param1"] = 15, ["z"] = 3, ["name"] = "default:diamondblock"}, {["x"] = 24, ["meta"] = {["fields"] = {}, ["inventory"] = {}}, ["param2"] = 0, ["y"] = 1, ["param1"] = 15, ["z"] = 4, ["name"] = "default:diamondblock"}, {["x"] = 24, ["meta"] = {["fields"] = {}, ["inventory"] = {}}, ["param2"] = 0, ["y"] = 1, ["param1"] = 15, ["z"] = 5, ["name"] = "default:diamondblock"}, {["x"] = 24, ["meta"] = {["fields"] = {}, ["inventory"] = {}}, ["param2"] = 0, ["y"] = 2, ["param1"] = 15, ["z"] = 1, ["name"] = "default:diamondblock"}, {["x"] = 24, ["meta"] = {["fields"] = {}, ["inventory"] = {}}, ["param2"] = 0, ["y"] = 2, ["param1"] = 15, ["z"] = 2, ["name"] = "default:diamondblock"}, {["x"] = 24, ["meta"] = {["fields"] = {}, ["inventory"] = {}}, ["param2"] = 0, ["y"] = 2, ["param1"] = 15, ["z"] = 3, ["name"] = "default:diamondblock"}, {["x"] = 24, ["meta"] = {["fields"] = {}, ["inventory"] = {}}, ["param2"] = 0, ["y"] = 2, ["param1"] = 15, ["z"] = 4, ["name"] = "default:diamondblock"}, {["x"] = 24, ["meta"] = {["fields"] = {}, ["inventory"] = {}}, ["param2"] = 0, ["y"] = 2, ["param1"] = 15, ["z"] = 5, ["name"] = "default:diamondblock"}, {["x"] = 24, ["meta"] = {["fields"] = {}, ["inventory"] = {}}, ["param2"] = 0, ["y"] = 3, ["param1"] = 15, ["z"] = 1, ["name"] = "default:diamondblock"}, {["x"] = 24, ["meta"] = {["fields"] = {}, ["inventory"] = {}}, ["param2"] = 0, ["y"] = 3, ["param1"] = 15, ["z"] = 2, ["name"] = "default:diamondblock"}, {["x"] = 24, ["meta"] = {["fields"] = {}, ["inventory"] = {}}, ["param2"] = 0, ["y"] = 3, ["param1"] = 15, ["z"] = 3, ["name"] = "default:diamondblock"}, {["x"] = 24, ["meta"] = {["fields"] = {}, ["inventory"] = {}}, ["param2"] = 0, ["y"] = 3, ["param1"] = 15, ["z"] = 4, ["name"] = "default:diamondblock"}, {["x"] = 24, ["meta"] = {["fields"] = {}, ["inventory"] = {}}, ["param2"] = 0, ["y"] = 3, ["param1"] = 15, ["z"] = 5, ["name"] = "default:diamondblock"}, {["x"] = 24, ["meta"] = {["fields"] = {}, ["inventory"] = {}}, ["param2"] = 0, ["y"] = 4, ["param1"] = 15, ["z"] = 1, ["name"] = "default:diamondblock"}, {["x"] = 24, ["meta"] = {["fields"] = {}, ["inventory"] = {}}, ["param2"] = 0, ["y"] = 4, ["param1"] = 15, ["z"] = 2, ["name"] = "default:diamondblock"}, {["x"] = 24, ["meta"] = {["fields"] = {}, ["inventory"] = {}}, ["param2"] = 0, ["y"] = 4, ["param1"] = 15, ["z"] = 3, ["name"] = "default:diamondblock"}, {["x"] = 24, ["meta"] = {["fields"] = {}, ["inventory"] = {}}, ["param2"] = 0, ["y"] = 4, ["param1"] = 15, ["z"] = 4, ["name"] = "default:diamondblock"}, {["x"] = 24, ["meta"] = {["fields"] = {}, ["inventory"] = {}}, ["param2"] = 0, ["y"] = 4, ["param1"] = 15, ["z"] = 5, ["name"] = "default:diamondblock"}, {["x"] = 24, ["meta"] = {["fields"] = {}, ["inventory"] = {}}, ["param2"] = 0, ["y"] = 5, ["param1"] = 15, ["z"] = 1, ["name"] = "default:diamondblock"}, {["x"] = 24, ["meta"] = {["fields"] = {}, ["inventory"] = {}}, ["param2"] = 0, ["y"] = 5, ["param1"] = 15, ["z"] = 2, ["name"] = "default:diamondblock"}, {["x"] = 24, ["meta"] = {["fields"] = {}, ["inventory"] = {}}, ["param2"] = 0, ["y"] = 5, ["param1"] = 15, ["z"] = 3, ["name"] = "default:diamondblock"}, {["x"] = 24, ["meta"] = {["fields"] = {}, ["inventory"] = {}}, ["param2"] = 0, ["y"] = 5, ["param1"] = 15, ["z"] = 4, ["name"] = "default:diamondblock"}, {["x"] = 24, ["meta"] = {["fields"] = {}, ["inventory"] = {}}, ["param2"] = 0, ["y"] = 5, ["param1"] = 15, ["z"] = 5, ["name"] = "default:diamondblock"}, {["x"] = 24, ["meta"] = {["fields"] = {}, ["inventory"] = {}}, ["param2"] = 0, ["y"] = 6, ["param1"] = 15, ["z"] = 1, ["name"] = "default:diamondblock"}, {["x"] = 24, ["meta"] = {["fields"] = {}, ["inventory"] = {}}, ["param2"] = 0, ["y"] = 6, ["param1"] = 15, ["z"] = 2, ["name"] = "default:diamondblock"}, {["x"] = 24, ["meta"] = {["fields"] = {}, ["inventory"] = {}}, ["param2"] = 0, ["y"] = 6, ["param1"] = 15, ["z"] = 3, ["name"] = "default:diamondblock"}, {["x"] = 24, ["meta"] = {["fields"] = {}, ["inventory"] = {}}, ["param2"] = 0, ["y"] = 6, ["param1"] = 15, ["z"] = 4, ["name"] = "default:diamondblock"}, {["x"] = 24, ["meta"] = {["fields"] = {}, ["inventory"] = {}}, ["param2"] = 0, ["y"] = 6, ["param1"] = 15, ["z"] = 5, ["name"] = "default:diamondblock"}, {["x"] = 24, ["meta"] = {["fields"] = {}, ["inventory"] = {}}, ["param2"] = 0, ["y"] = 7, ["param1"] = 15, ["z"] = 1, ["name"] = "default:diamondblock"}, {["x"] = 24, ["meta"] = {["fields"] = {}, ["inventory"] = {}}, ["param2"] = 0, ["y"] = 7, ["param1"] = 15, ["z"] = 2, ["name"] = "default:diamondblock"}, {["x"] = 24, ["meta"] = {["fields"] = {}, ["inventory"] = {}}, ["param2"] = 0, ["y"] = 7, ["param1"] = 15, ["z"] = 3, ["name"] = "default:diamondblock"}, {["x"] = 24, ["meta"] = {["fields"] = {}, ["inventory"] = {}}, ["param2"] = 0, ["y"] = 7, ["param1"] = 15, ["z"] = 4, ["name"] = "default:diamondblock"}, {["x"] = 24, ["meta"] = {["fields"] = {}, ["inventory"] = {}}, ["param2"] = 0, ["y"] = 7, ["param1"] = 15, ["z"] = 5, ["name"] = "default:diamondblock"}, {["x"] = 25, ["meta"] = {["fields"] = {}, ["inventory"] = {}}, ["param2"] = 0, ["y"] = 0, ["param1"] = 15, ["z"] = 1, ["name"] = "default:diamondblock"}, {["x"] = 25, ["meta"] = {["fields"] = {}, ["inventory"] = {}}, ["param2"] = 0, ["y"] = 0, ["param1"] = 15, ["z"] = 2, ["name"] = "default:diamondblock"}, {["x"] = 25, ["meta"] = {["fields"] = {}, ["inventory"] = {}}, ["param2"] = 0, ["y"] = 0, ["param1"] = 15, ["z"] = 3, ["name"] = "default:diamondblock"}, {["x"] = 25, ["meta"] = {["fields"] = {}, ["inventory"] = {}}, ["param2"] = 0, ["y"] = 0, ["param1"] = 15, ["z"] = 4, ["name"] = "default:diamondblock"}, {["x"] = 25, ["meta"] = {["fields"] = {}, ["inventory"] = {}}, ["param2"] = 0, ["y"] = 0, ["param1"] = 15, ["z"] = 5, ["name"] = "default:diamondblock"}, {["x"] = 25, ["meta"] = {["fields"] = {}, ["inventory"] = {}}, ["param2"] = 0, ["y"] = 1, ["param1"] = 15, ["z"] = 1, ["name"] = "default:diamondblock"}, {["x"] = 25, ["meta"] = {["fields"] = {}, ["inventory"] = {}}, ["param2"] = 0, ["y"] = 1, ["param1"] = 15, ["z"] = 2, ["name"] = "default:diamondblock"}, {["x"] = 25, ["meta"] = {["fields"] = {}, ["inventory"] = {}}, ["param2"] = 0, ["y"] = 1, ["param1"] = 15, ["z"] = 3, ["name"] = "default:diamondblock"}, {["x"] = 25, ["meta"] = {["fields"] = {}, ["inventory"] = {}}, ["param2"] = 0, ["y"] = 1, ["param1"] = 15, ["z"] = 4, ["name"] = "default:diamondblock"}, {["x"] = 25, ["meta"] = {["fields"] = {}, ["inventory"] = {}}, ["param2"] = 0, ["y"] = 1, ["param1"] = 15, ["z"] = 5, ["name"] = "default:diamondblock"}, {["x"] = 25, ["meta"] = {["fields"] = {}, ["inventory"] = {}}, ["param2"] = 0, ["y"] = 2, ["param1"] = 15, ["z"] = 1, ["name"] = "default:diamondblock"}, {["x"] = 25, ["meta"] = {["fields"] = {}, ["inventory"] = {}}, ["param2"] = 0, ["y"] = 2, ["param1"] = 15, ["z"] = 2, ["name"] = "default:diamondblock"}, {["x"] = 25, ["meta"] = {["fields"] = {}, ["inventory"] = {}}, ["param2"] = 0, ["y"] = 2, ["param1"] = 15, ["z"] = 3, ["name"] = "default:diamondblock"}, {["x"] = 25, ["meta"] = {["fields"] = {}, ["inventory"] = {}}, ["param2"] = 0, ["y"] = 2, ["param1"] = 15, ["z"] = 4, ["name"] = "default:diamondblock"}, {["x"] = 25, ["meta"] = {["fields"] = {}, ["inventory"] = {}}, ["param2"] = 0, ["y"] = 2, ["param1"] = 15, ["z"] = 5, ["name"] = "default:diamondblock"}, {["x"] = 25, ["meta"] = {["fields"] = {}, ["inventory"] = {}}, ["param2"] = 0, ["y"] = 3, ["param1"] = 15, ["z"] = 1, ["name"] = "default:diamondblock"}, {["x"] = 25, ["meta"] = {["fields"] = {}, ["inventory"] = {}}, ["param2"] = 0, ["y"] = 3, ["param1"] = 15, ["z"] = 2, ["name"] = "default:diamondblock"}, {["x"] = 25, ["meta"] = {["fields"] = {}, ["inventory"] = {}}, ["param2"] = 0, ["y"] = 3, ["param1"] = 15, ["z"] = 3, ["name"] = "default:diamondblock"}, {["x"] = 25, ["meta"] = {["fields"] = {}, ["inventory"] = {}}, ["param2"] = 0, ["y"] = 3, ["param1"] = 15, ["z"] = 4, ["name"] = "default:diamondblock"}, {["x"] = 25, ["meta"] = {["fields"] = {}, ["inventory"] = {}}, ["param2"] = 0, ["y"] = 3, ["param1"] = 15, ["z"] = 5, ["name"] = "default:diamondblock"}, {["x"] = 25, ["meta"] = {["fields"] = {}, ["inventory"] = {}}, ["param2"] = 0, ["y"] = 4, ["param1"] = 15, ["z"] = 1, ["name"] = "default:diamondblock"}, {["x"] = 25, ["meta"] = {["fields"] = {}, ["inventory"] = {}}, ["param2"] = 0, ["y"] = 4, ["param1"] = 15, ["z"] = 2, ["name"] = "default:diamondblock"}, {["x"] = 25, ["meta"] = {["fields"] = {}, ["inventory"] = {}}, ["param2"] = 0, ["y"] = 4, ["param1"] = 15, ["z"] = 3, ["name"] = "default:diamondblock"}, {["x"] = 25, ["meta"] = {["fields"] = {}, ["inventory"] = {}}, ["param2"] = 0, ["y"] = 4, ["param1"] = 15, ["z"] = 4, ["name"] = "default:diamondblock"}, {["x"] = 25, ["meta"] = {["fields"] = {}, ["inventory"] = {}}, ["param2"] = 0, ["y"] = 4, ["param1"] = 15, ["z"] = 5, ["name"] = "default:diamondblock"}, {["x"] = 25, ["meta"] = {["fields"] = {}, ["inventory"] = {}}, ["param2"] = 0, ["y"] = 5, ["param1"] = 15, ["z"] = 1, ["name"] = "default:diamondblock"}, {["x"] = 25, ["meta"] = {["fields"] = {}, ["inventory"] = {}}, ["param2"] = 0, ["y"] = 5, ["param1"] = 15, ["z"] = 2, ["name"] = "default:diamondblock"}, {["x"] = 25, ["meta"] = {["fields"] = {}, ["inventory"] = {}}, ["param2"] = 0, ["y"] = 5, ["param1"] = 15, ["z"] = 3, ["name"] = "default:diamondblock"}, {["x"] = 25, ["meta"] = {["fields"] = {}, ["inventory"] = {}}, ["param2"] = 0, ["y"] = 5, ["param1"] = 15, ["z"] = 4, ["name"] = "default:diamondblock"}, {["x"] = 25, ["meta"] = {["fields"] = {}, ["inventory"] = {}}, ["param2"] = 0, ["y"] = 5, ["param1"] = 15, ["z"] = 5, ["name"] = "default:diamondblock"}, {["x"] = 25, ["meta"] = {["fields"] = {}, ["inventory"] = {}}, ["param2"] = 0, ["y"] = 6, ["param1"] = 15, ["z"] = 1, ["name"] = "default:diamondblock"}, {["x"] = 25, ["meta"] = {["fields"] = {}, ["inventory"] = {}}, ["param2"] = 0, ["y"] = 6, ["param1"] = 15, ["z"] = 2, ["name"] = "default:diamondblock"}, {["x"] = 25, ["meta"] = {["fields"] = {}, ["inventory"] = {}}, ["param2"] = 0, ["y"] = 6, ["param1"] = 15, ["z"] = 3, ["name"] = "default:diamondblock"}, {["x"] = 25, ["meta"] = {["fields"] = {}, ["inventory"] = {}}, ["param2"] = 0, ["y"] = 6, ["param1"] = 15, ["z"] = 4, ["name"] = "default:diamondblock"}, {["x"] = 25, ["meta"] = {["fields"] = {}, ["inventory"] = {}}, ["param2"] = 0, ["y"] = 6, ["param1"] = 15, ["z"] = 5, ["name"] = "default:diamondblock"}, {["x"] = 25, ["meta"] = {["fields"] = {}, ["inventory"] = {}}, ["param2"] = 0, ["y"] = 7, ["param1"] = 15, ["z"] = 1, ["name"] = "default:diamondblock"}, {["x"] = 25, ["meta"] = {["fields"] = {}, ["inventory"] = {}}, ["param2"] = 0, ["y"] = 7, ["param1"] = 15, ["z"] = 2, ["name"] = "default:diamondblock"}, {["x"] = 25, ["meta"] = {["fields"] = {}, ["inventory"] = {}}, ["param2"] = 0, ["y"] = 7, ["param1"] = 15, ["z"] = 3, ["name"] = "default:diamondblock"}, {["x"] = 25, ["meta"] = {["fields"] = {}, ["inventory"] = {}}, ["param2"] = 0, ["y"] = 7, ["param1"] = 15, ["z"] = 4, ["name"] = "default:diamondblock"}, {["x"] = 25, ["meta"] = {["fields"] = {}, ["inventory"] = {}}, ["param2"] = 0, ["y"] = 7, ["param1"] = 15, ["z"] = 5, ["name"] = "default:diamondblock"}, {["x"] = 26, ["meta"] = {["fields"] = {}, ["inventory"] = {}}, ["param2"] = 0, ["y"] = 0, ["param1"] = 15, ["z"] = 1, ["name"] = "default:diamondblock"}, {["x"] = 26, ["meta"] = {["fields"] = {}, ["inventory"] = {}}, ["param2"] = 0, ["y"] = 0, ["param1"] = 15, ["z"] = 2, ["name"] = "default:diamondblock"}, {["x"] = 26, ["meta"] = {["fields"] = {}, ["inventory"] = {}}, ["param2"] = 0, ["y"] = 0, ["param1"] = 15, ["z"] = 3, ["name"] = "default:diamondblock"}, {["x"] = 26, ["meta"] = {["fields"] = {}, ["inventory"] = {}}, ["param2"] = 0, ["y"] = 0, ["param1"] = 15, ["z"] = 4, ["name"] = "default:diamondblock"}, {["x"] = 26, ["meta"] = {["fields"] = {}, ["inventory"] = {}}, ["param2"] = 0, ["y"] = 0, ["param1"] = 15, ["z"] = 5, ["name"] = "default:diamondblock"}, {["x"] = 26, ["meta"] = {["fields"] = {}, ["inventory"] = {}}, ["param2"] = 0, ["y"] = 1, ["param1"] = 15, ["z"] = 1, ["name"] = "default:diamondblock"}, {["x"] = 26, ["meta"] = {["fields"] = {}, ["inventory"] = {}}, ["param2"] = 0, ["y"] = 1, ["param1"] = 15, ["z"] = 2, ["name"] = "default:diamondblock"}, {["x"] = 26, ["meta"] = {["fields"] = {}, ["inventory"] = {}}, ["param2"] = 0, ["y"] = 1, ["param1"] = 15, ["z"] = 3, ["name"] = "default:diamondblock"}, {["x"] = 26, ["meta"] = {["fields"] = {}, ["inventory"] = {}}, ["param2"] = 0, ["y"] = 1, ["param1"] = 15, ["z"] = 4, ["name"] = "default:diamondblock"}, {["x"] = 26, ["meta"] = {["fields"] = {}, ["inventory"] = {}}, ["param2"] = 0, ["y"] = 1, ["param1"] = 15, ["z"] = 5, ["name"] = "default:diamondblock"}, {["x"] = 26, ["meta"] = {["fields"] = {}, ["inventory"] = {}}, ["param2"] = 0, ["y"] = 2, ["param1"] = 15, ["z"] = 1, ["name"] = "default:diamondblock"}, {["x"] = 26, ["meta"] = {["fields"] = {}, ["inventory"] = {}}, ["param2"] = 0, ["y"] = 2, ["param1"] = 15, ["z"] = 2, ["name"] = "default:diamondblock"}, {["x"] = 26, ["meta"] = {["fields"] = {}, ["inventory"] = {}}, ["param2"] = 0, ["y"] = 2, ["param1"] = 15, ["z"] = 3, ["name"] = "default:diamondblock"}, {["x"] = 26, ["meta"] = {["fields"] = {}, ["inventory"] = {}}, ["param2"] = 0, ["y"] = 2, ["param1"] = 15, ["z"] = 4, ["name"] = "default:diamondblock"}, {["x"] = 26, ["meta"] = {["fields"] = {}, ["inventory"] = {}}, ["param2"] = 0, ["y"] = 2, ["param1"] = 15, ["z"] = 5, ["name"] = "default:diamondblock"}, {["x"] = 26, ["meta"] = {["fields"] = {}, ["inventory"] = {}}, ["param2"] = 0, ["y"] = 3, ["param1"] = 15, ["z"] = 1, ["name"] = "default:diamondblock"}, {["x"] = 26, ["meta"] = {["fields"] = {}, ["inventory"] = {}}, ["param2"] = 0, ["y"] = 3, ["param1"] = 15, ["z"] = 2, ["name"] = "default:diamondblock"}, {["x"] = 26, ["meta"] = {["fields"] = {}, ["inventory"] = {}}, ["param2"] = 0, ["y"] = 3, ["param1"] = 15, ["z"] = 3, ["name"] = "default:diamondblock"}, {["x"] = 26, ["meta"] = {["fields"] = {}, ["inventory"] = {}}, ["param2"] = 0, ["y"] = 3, ["param1"] = 15, ["z"] = 4, ["name"] = "default:diamondblock"}, {["x"] = 26, ["meta"] = {["fields"] = {}, ["inventory"] = {}}, ["param2"] = 0, ["y"] = 3, ["param1"] = 15, ["z"] = 5, ["name"] = "default:diamondblock"}, {["x"] = 26, ["meta"] = {["fields"] = {}, ["inventory"] = {}}, ["param2"] = 0, ["y"] = 4, ["param1"] = 15, ["z"] = 1, ["name"] = "default:diamondblock"}, {["x"] = 26, ["meta"] = {["fields"] = {}, ["inventory"] = {}}, ["param2"] = 0, ["y"] = 4, ["param1"] = 15, ["z"] = 2, ["name"] = "default:diamondblock"}, {["x"] = 26, ["meta"] = {["fields"] = {}, ["inventory"] = {}}, ["param2"] = 0, ["y"] = 4, ["param1"] = 15, ["z"] = 3, ["name"] = "default:diamondblock"}, {["x"] = 26, ["meta"] = {["fields"] = {}, ["inventory"] = {}}, ["param2"] = 0, ["y"] = 4, ["param1"] = 15, ["z"] = 4, ["name"] = "default:diamondblock"}, {["x"] = 26, ["meta"] = {["fields"] = {}, ["inventory"] = {}}, ["param2"] = 0, ["y"] = 4, ["param1"] = 15, ["z"] = 5, ["name"] = "default:diamondblock"}, {["x"] = 26, ["meta"] = {["fields"] = {}, ["inventory"] = {}}, ["param2"] = 0, ["y"] = 5, ["param1"] = 15, ["z"] = 1, ["name"] = "default:diamondblock"}, {["x"] = 26, ["meta"] = {["fields"] = {}, ["inventory"] = {}}, ["param2"] = 0, ["y"] = 5, ["param1"] = 15, ["z"] = 2, ["name"] = "default:diamondblock"}, {["x"] = 26, ["meta"] = {["fields"] = {}, ["inventory"] = {}}, ["param2"] = 0, ["y"] = 5, ["param1"] = 15, ["z"] = 3, ["name"] = "default:diamondblock"}, {["x"] = 26, ["meta"] = {["fields"] = {}, ["inventory"] = {}}, ["param2"] = 0, ["y"] = 5, ["param1"] = 15, ["z"] = 4, ["name"] = "default:diamondblock"}, {["x"] = 26, ["meta"] = {["fields"] = {}, ["inventory"] = {}}, ["param2"] = 0, ["y"] = 5, ["param1"] = 15, ["z"] = 5, ["name"] = "default:diamondblock"}, {["x"] = 26, ["meta"] = {["fields"] = {}, ["inventory"] = {}}, ["param2"] = 0, ["y"] = 6, ["param1"] = 15, ["z"] = 1, ["name"] = "default:diamondblock"}, {["x"] = 26, ["meta"] = {["fields"] = {}, ["inventory"] = {}}, ["param2"] = 0, ["y"] = 6, ["param1"] = 15, ["z"] = 2, ["name"] = "default:diamondblock"}, {["x"] = 26, ["meta"] = {["fields"] = {}, ["inventory"] = {}}, ["param2"] = 0, ["y"] = 6, ["param1"] = 15, ["z"] = 3, ["name"] = "default:diamondblock"}, {["x"] = 26, ["meta"] = {["fields"] = {}, ["inventory"] = {}}, ["param2"] = 0, ["y"] = 6, ["param1"] = 15, ["z"] = 4, ["name"] = "default:diamondblock"}, {["x"] = 26, ["meta"] = {["fields"] = {}, ["inventory"] = {}}, ["param2"] = 0, ["y"] = 6, ["param1"] = 15, ["z"] = 5, ["name"] = "default:diamondblock"}, {["x"] = 26, ["meta"] = {["fields"] = {}, ["inventory"] = {}}, ["param2"] = 0, ["y"] = 7, ["param1"] = 15, ["z"] = 1, ["name"] = "default:diamondblock"}, {["x"] = 26, ["meta"] = {["fields"] = {}, ["inventory"] = {}}, ["param2"] = 0, ["y"] = 7, ["param1"] = 15, ["z"] = 2, ["name"] = "default:diamondblock"}, {["x"] = 26, ["meta"] = {["fields"] = {}, ["inventory"] = {}}, ["param2"] = 0, ["y"] = 7, ["param1"] = 15, ["z"] = 3, ["name"] = "default:diamondblock"}, {["x"] = 26, ["meta"] = {["fields"] = {}, ["inventory"] = {}}, ["param2"] = 0, ["y"] = 7, ["param1"] = 15, ["z"] = 4, ["name"] = "default:diamondblock"}, {["x"] = 26, ["meta"] = {["fields"] = {}, ["inventory"] = {}}, ["param2"] = 0, ["y"] = 7, ["param1"] = 15, ["z"] = 5, ["name"] = "default:diamondblock"}, {["x"] = 27, ["meta"] = {["fields"] = {}, ["inventory"] = {}}, ["param2"] = 0, ["y"] = 0, ["param1"] = 15, ["z"] = 1, ["name"] = "default:diamondblock"}, {["x"] = 27, ["meta"] = {["fields"] = {}, ["inventory"] = {}}, ["param2"] = 0, ["y"] = 0, ["param1"] = 15, ["z"] = 2, ["name"] = "default:diamondblock"}, {["x"] = 27, ["meta"] = {["fields"] = {}, ["inventory"] = {}}, ["param2"] = 0, ["y"] = 0, ["param1"] = 15, ["z"] = 3, ["name"] = "default:diamondblock"}, {["x"] = 27, ["meta"] = {["fields"] = {}, ["inventory"] = {}}, ["param2"] = 0, ["y"] = 0, ["param1"] = 15, ["z"] = 4, ["name"] = "default:diamondblock"}, {["x"] = 27, ["meta"] = {["fields"] = {}, ["inventory"] = {}}, ["param2"] = 0, ["y"] = 0, ["param1"] = 15, ["z"] = 5, ["name"] = "default:diamondblock"}, {["x"] = 27, ["meta"] = {["fields"] = {}, ["inventory"] = {}}, ["param2"] = 0, ["y"] = 1, ["param1"] = 15, ["z"] = 1, ["name"] = "default:diamondblock"}, {["x"] = 27, ["meta"] = {["fields"] = {}, ["inventory"] = {}}, ["param2"] = 0, ["y"] = 1, ["param1"] = 15, ["z"] = 2, ["name"] = "default:diamondblock"}, {["x"] = 27, ["meta"] = {["fields"] = {}, ["inventory"] = {}}, ["param2"] = 0, ["y"] = 1, ["param1"] = 15, ["z"] = 3, ["name"] = "default:diamondblock"}, {["x"] = 27, ["meta"] = {["fields"] = {}, ["inventory"] = {}}, ["param2"] = 0, ["y"] = 1, ["param1"] = 15, ["z"] = 4, ["name"] = "default:diamondblock"}, {["x"] = 27, ["meta"] = {["fields"] = {}, ["inventory"] = {}}, ["param2"] = 0, ["y"] = 1, ["param1"] = 15, ["z"] = 5, ["name"] = "default:diamondblock"}, {["x"] = 27, ["meta"] = {["fields"] = {}, ["inventory"] = {}}, ["param2"] = 0, ["y"] = 2, ["param1"] = 15, ["z"] = 1, ["name"] = "default:diamondblock"}, {["x"] = 27, ["meta"] = {["fields"] = {}, ["inventory"] = {}}, ["param2"] = 0, ["y"] = 2, ["param1"] = 15, ["z"] = 2, ["name"] = "default:diamondblock"}, {["x"] = 27, ["meta"] = {["fields"] = {}, ["inventory"] = {}}, ["param2"] = 0, ["y"] = 2, ["param1"] = 15, ["z"] = 3, ["name"] = "default:diamondblock"}, {["x"] = 27, ["meta"] = {["fields"] = {}, ["inventory"] = {}}, ["param2"] = 0, ["y"] = 2, ["param1"] = 15, ["z"] = 4, ["name"] = "default:diamondblock"}, {["x"] = 27, ["meta"] = {["fields"] = {}, ["inventory"] = {}}, ["param2"] = 0, ["y"] = 2, ["param1"] = 15, ["z"] = 5, ["name"] = "default:diamondblock"}, {["x"] = 27, ["meta"] = {["fields"] = {}, ["inventory"] = {}}, ["param2"] = 0, ["y"] = 3, ["param1"] = 15, ["z"] = 1, ["name"] = "default:diamondblock"}, {["x"] = 27, ["meta"] = {["fields"] = {}, ["inventory"] = {}}, ["param2"] = 0, ["y"] = 3, ["param1"] = 15, ["z"] = 2, ["name"] = "default:diamondblock"}, {["x"] = 27, ["meta"] = {["fields"] = {}, ["inventory"] = {}}, ["param2"] = 0, ["y"] = 3, ["param1"] = 15, ["z"] = 3, ["name"] = "default:diamondblock"}, {["x"] = 27, ["meta"] = {["fields"] = {}, ["inventory"] = {}}, ["param2"] = 0, ["y"] = 3, ["param1"] = 15, ["z"] = 4, ["name"] = "default:diamondblock"}, {["x"] = 27, ["meta"] = {["fields"] = {}, ["inventory"] = {}}, ["param2"] = 0, ["y"] = 3, ["param1"] = 15, ["z"] = 5, ["name"] = "default:diamondblock"}, {["x"] = 27, ["meta"] = {["fields"] = {}, ["inventory"] = {}}, ["param2"] = 0, ["y"] = 4, ["param1"] = 15, ["z"] = 1, ["name"] = "default:diamondblock"}, {["x"] = 27, ["meta"] = {["fields"] = {}, ["inventory"] = {}}, ["param2"] = 0, ["y"] = 4, ["param1"] = 15, ["z"] = 2, ["name"] = "default:diamondblock"}, {["x"] = 27, ["meta"] = {["fields"] = {}, ["inventory"] = {}}, ["param2"] = 0, ["y"] = 4, ["param1"] = 15, ["z"] = 3, ["name"] = "default:diamondblock"}, {["x"] = 27, ["meta"] = {["fields"] = {}, ["inventory"] = {}}, ["param2"] = 0, ["y"] = 4, ["param1"] = 15, ["z"] = 4, ["name"] = "default:diamondblock"}, {["x"] = 27, ["meta"] = {["fields"] = {}, ["inventory"] = {}}, ["param2"] = 0, ["y"] = 4, ["param1"] = 15, ["z"] = 5, ["name"] = "default:diamondblock"}, {["x"] = 27, ["meta"] = {["fields"] = {}, ["inventory"] = {}}, ["param2"] = 0, ["y"] = 5, ["param1"] = 15, ["z"] = 1, ["name"] = "default:diamondblock"}, {["x"] = 27, ["meta"] = {["fields"] = {}, ["inventory"] = {}}, ["param2"] = 0, ["y"] = 5, ["param1"] = 15, ["z"] = 2, ["name"] = "default:diamondblock"}, {["x"] = 27, ["meta"] = {["fields"] = {}, ["inventory"] = {}}, ["param2"] = 0, ["y"] = 5, ["param1"] = 15, ["z"] = 3, ["name"] = "default:diamondblock"}, {["x"] = 27, ["meta"] = {["fields"] = {}, ["inventory"] = {}}, ["param2"] = 0, ["y"] = 5, ["param1"] = 15, ["z"] = 4, ["name"] = "default:diamondblock"}, {["x"] = 27, ["meta"] = {["fields"] = {}, ["inventory"] = {}}, ["param2"] = 0, ["y"] = 5, ["param1"] = 15, ["z"] = 5, ["name"] = "default:diamondblock"}, {["x"] = 27, ["meta"] = {["fields"] = {}, ["inventory"] = {}}, ["param2"] = 0, ["y"] = 6, ["param1"] = 15, ["z"] = 1, ["name"] = "default:diamondblock"}, {["x"] = 27, ["meta"] = {["fields"] = {}, ["inventory"] = {}}, ["param2"] = 0, ["y"] = 6, ["param1"] = 15, ["z"] = 2, ["name"] = "default:diamondblock"}, {["x"] = 27, ["meta"] = {["fields"] = {}, ["inventory"] = {}}, ["param2"] = 0, ["y"] = 6, ["param1"] = 15, ["z"] = 3, ["name"] = "default:diamondblock"}, {["x"] = 27, ["meta"] = {["fields"] = {}, ["inventory"] = {}}, ["param2"] = 0, ["y"] = 6, ["param1"] = 15, ["z"] = 4, ["name"] = "default:diamondblock"}, {["x"] = 27, ["meta"] = {["fields"] = {}, ["inventory"] = {}}, ["param2"] = 0, ["y"] = 6, ["param1"] = 15, ["z"] = 5, ["name"] = "default:diamondblock"}, {["x"] = 27, ["meta"] = {["fields"] = {}, ["inventory"] = {}}, ["param2"] = 0, ["y"] = 7, ["param1"] = 15, ["z"] = 1, ["name"] = "default:diamondblock"}, {["x"] = 27, ["meta"] = {["fields"] = {}, ["inventory"] = {}}, ["param2"] = 0, ["y"] = 7, ["param1"] = 15, ["z"] = 2, ["name"] = "default:diamondblock"}, {["x"] = 27, ["meta"] = {["fields"] = {}, ["inventory"] = {}}, ["param2"] = 0, ["y"] = 7, ["param1"] = 15, ["z"] = 3, ["name"] = "default:diamondblock"}, {["x"] = 27, ["meta"] = {["fields"] = {}, ["inventory"] = {}}, ["param2"] = 0, ["y"] = 7, ["param1"] = 15, ["z"] = 4, ["name"] = "default:diamondblock"}, {["x"] = 27, ["meta"] = {["fields"] = {}, ["inventory"] = {}}, ["param2"] = 0, ["y"] = 7, ["param1"] = 15, ["z"] = 5, ["name"] = "default:diamondblock"}}